Workbook

Sheet 사용법
A1: 오수관로 수리계산 검증 시트 (BC 노선 30개 관로)
A3: 목적: 종단 편집기가 하는 수리계산을 엑셀 함수로 그대로 풀어, 계산이 제대로 되는지 눈으로 확인합니다.
A5: 시트 구성
A6: 설정 : 판정 기준값 (최소유속, 토피 등). 파란 글씨 = 직접 바꿀 수 있는 입력값
A7: 입력 : BC 노선 입력자료 (PipeTools 수리계산 시트와 같은 값). 파란 글씨 = 입력값, 바꾸면 전체가 다시 계산됨
A8: 계산 : 유량 누가 → 만관 유량·유속 → 등류수심·실유속 → 여유율·유속·토피 판정 (모두 함수)
A9: 수심반복 : 등류수심을 구하는 이분법 40회를 칸마다 풀어 쓴 시트 (엑셀에는 반복 계산 함수가 없어서)
A10: 검증 : 엑셀 계산값 · PipeTools 결과(rpt) · 종단 편집기 계산값을 나란히 놓고 차이를 표시
A12: 계산 순서와 식
A13: 1. 자체 인구 = 유역면적 × 인구밀도, 누가 인구 = 자체 인구 + 바로 윗 관로의 누가 인구
A14: 2. 자체 오수량 [m³/s] = (오수원단위 × P.F + 지하수원단위) × 자체 인구 / 86,400,000 + 직접 유입
A15: 누가 유량 Q = 자체 오수량 + 바로 윗 관로의 누가 유량
... A29: · 입력값은 사용자가 올린 PipeTools BC 노선 자료에서 읽은 값입니다.

Sheet 설정
A1: 판정 기준 설정
A3: 항목 | B3: 값 | C3: 설명
A4: 최소 유속 [m/s] | B4: 0.6 | C4: 이 값 미만이면 유지관리(주의)
A5: 최대 유속 [m/s] | B5: 3 | C5: 초과하면 NG
A6: 유지관리 하한 유속 [m/s] | B6: 0.3 | C6: 미만이면 NG (불량)
A7: 최소 토피 [m] | B7: 1 | C7: 상류단 기준 (PipeTools rpt 와 같음)
A8: 급경사 기준 [‰] | B8: 100 | C8: 이 경사 이상에서 유속 NG 는 구배10.0%이상 으로 표시
A9: 허용 수심비 (원형) | B9: 1 | C9: 1.0 = 만관유량이 허용유량 (이 시트는 1.0 만 지원)
A10: θmax (수심비 0.938 의 중심각) [rad] | B10: =2*ACOS(1-2*0.938) -> 5.2766032 | C10: 이분법 탐색 범위 상한. 이보다 큰 유량은 만관으로 봄 (PipeTools 와 같은 처리)
A11: 일 환산 상수 | B11: 86400000 | C11: L/일 → m³/s : ÷ 86,400,000
A13: 여유율 (하수도시설기준 오수관거)
A14: 관경 상한 [mm] | B14: 여유율 | C14: 비고
A15: 600 | B15: 1 | C15: 600 이하
A16: 1500 | B16: 0.5 | C16: 700 ~ 1500
A17: 99999 | B17: 0.25 | C17: 1650 이상

Sheet 입력
A1: 입력 자료 (BC 노선)
A2: 파란 글씨 = PipeTools 수리계산 시트의 값. 직접 바꿔 보면 계산 시트가 따라 바뀝니다.
A4: 관로번호 | B4: 상류맨홀 | C4: 하류맨홀 | D4: 연장 L [m] | E4: 관경 D [mm] | F4: 상류 관저고 [m] | G4: 하류 관저고 [m] | H4: 상류 지반고 [m] | I4: 하류 지반고 [m] | J4: 조도계수 n | K4: 유역면적 [ha] | L4: 인구밀도 [인/ha] | M4: 오수원단위 [L/인·일] | N4: 지하수원단위 [L/인·일] | O4: P.F | P4: 직접 유입 [m³/s]
A5: BC-01 | B5: BC-01 | C5: BC-02 | D5: 10 | E5: 200 | F5: 45.2 | G5: 45.07 | H5: 46.55 | I5: 46.47 | J5: 0.011 | K5: 0 | L5: 0 | M5: 0 | N5: 0 | O5: 1 | P5: 0.0017890046
A6: BC-02 | B6: BC-02 | C6: BC-03 | D6: 50 | E6: 200 | F6: 45.07 | G6: 44.5 | H6: 46.47 | I6: 45.7 | J6: 0.011 | K6: 0 | L6: 0 | M6: 0 | N6: 0 | O6: 1 | P6: 0
A7: BC-03 | B7: BC-03 | C7: BC-04 | D7: 50 | E7: 200 | F7: 44.5 | G7: 43.54 | H7: 45.7 | I7: 44.74 | J7: 0.011 | K7: 0 | L7: 0 | M7: 0 | N7: 0 | O7: 1 | P7: 0
A8: BC-04 | B8: BC-04 | C8: BC-05 | D8: 50 | E8: 200 | F8: 43.54 | G8: 42.33 | H8: 44.74 | I8: 43.53 | J8: 0.011 | K8: 0 | L8: 0 | M8: 0 | N8: 0 | O8: 1 | P8: 0
A9: BC-05 | B9: BC-05 | C9: BC-06 | D9: 50 | E9: 200 | F9: 42.33 | G9: 41.06 | H9: 43.53 | I9: 42.26 | J9: 0.011 | K9: 0 | L9: 0 | M9: 0 | N9: 0 | O9: 1 | P9: 0
A10: BC-06 | B10: BC-06 | C10: BC-07 | D10: 50 | E10: 200 | F10: 41.06 | G10: 40.53 | H10: 42.26 | I10: 41.73 | J10: 0.011 | K10: 0 | L10: 0 | M10: 0 | N10: 0 | O10: 1 | P10: 0
A11: BC-07 | B11: BC-07 | C11: BC-08 | D11: 50 | E11: 200 | F11: 40.53 | G11: 39.94 | H11: 41.73 | I11: 41.14 | J11: 0.011 | K11: 0 | L11: 0 | M11: 0 | N11: 0 | O11: 1 | P11: 0
A12: BC-08 | B12: BC-08 | C12: BC-09 | D12: 40 | E12: 200 | F12: 39.94 | G12: 39.21 | H12: 41.14 | I12: 40.41 | J12: 0.011 | K12: 0 | L12: 0 | M12: 0 | N12: 0 | O12: 1 | P12: 0
A13: BC-09 | B13: BC-09 | C13: BC-10 | D13: 29 | E13: 200 | F13: 39.21 | G13: 38.46 | H13: 40.41 | I13: 39.56 | J13: 0.011 | K13: 0 | L13: 0 | M13: 0 | N13: 0 | O13: 1 | P13: 0
A14: BC-10 | B14: BC-10 | C14: BC-11 | D14: 30 | E14: 200 | F14: 38.46 | G14: 37.97 | H14: 39.56 | I14: 39.17 | J14: 0.011 | K14: 0 | L14: 0 | M14: 0 | N14: 0 | O14: 1 | P14: 0
A15: BC-11 | B15: BC-11 | C15: BC-12 | D15: 40 | E15: 200 | F15: 37.97 | G15: 37.51 | H15: 39.17 | I15: 38.71 | J15: 0.011 | K15: 0 | L15: 0 | M15: 0 | N15: 0 | O15: 1 | P15: 0
A16: BC-12 | B16: BC-12 | C16: BC-13 | D16: 40 | E16: 200 | F16: 37.51 | G16: 36.97 | H16: 38.71 | I16: 38.17 | J16: 0.011 | K16: 0 | L16: 0 | M16: 0 | N16: 0 | O16: 1 | P16: 0
... A34: BC-30 | B34: BC-30 | C34: BC-31 | D34: 14 | E34: 200 | F34: 30.96 | G34: 30.91 | H34: 31.96 | I34: 32.46 | J34: 0.011 | K34: 0 | L34: 0 | M34: 0 | N34: 0 | O34: 1 | P34: 0

Sheet 수심반복
A1: 등류수심 이분법 (40회) — 중심각 θ 를 0 ~ θmax 에서 반씩 줄여 Q(θ) = Q 가 되는 값을 찾음
A2: θ[k] = θ[k-1] ± θmax / 2^(k+1) (Q(θ[k-1]) < Q 이면 +, 아니면 −). 마지막 θ 를 계산 시트가 가져감
A4: 관로 | B4: 목표 Q [m³/s] | C4: D [m] | D4: S [m/m] | E4: n | F4: θ0 | G4: Q(θ0) | H4: θ1 | I4: Q(θ1) | J4: θ2 | K4: Q(θ2) | L4: θ3 | M4: Q(θ3) | N4: θ4 | O4: Q(θ4) | P4: θ5 | Q4: Q(θ5) | R4: θ6 | S4: Q(θ6) | T4: θ7 | U4: Q(θ7) | V4: θ8 | W4: Q(θ8) | X4: θ9 | Y4: Q(θ9) | Z4: θ10 | AA4: Q(θ10) | AB4: θ11 | AC4: Q(θ11) | AD4: θ12 | AE4: Q(θ12) | AF4: θ13 | AG4: Q(θ13) | AH4: θ14 | AI4: Q(θ14) | AJ4: θ15 | AK4: Q(θ15) | AL4: θ16 | AM4: Q(θ16) | AN4: θ17 | AO4: Q(θ17) | AP4: θ18 | AQ4: Q(θ18) | AR4: θ19 | AS4: Q(θ19) | AT4: θ20 | AU4: Q(θ20) | AV4: θ21 | AW4: Q(θ21) | AX4: θ22 | AY4: Q(θ22) | AZ4: θ23 | BA4: Q(θ23) | BB4: θ24 | BC4: Q(θ24) | BD4: θ25 | BE4: Q(θ25) | BF4: θ26 | BG4: Q(θ26) | BH4: θ27 | BI4: Q(θ27) | BJ4: θ28 | BK4: Q(θ28) | BL4: θ29 | BM4: Q(θ29) | BN4: θ30 | BO4: Q(θ30) | BP4: θ31 | BQ4: Q(θ31) | BR4: θ32 | BS4: Q(θ32) | BT4: θ33 | BU4: Q(θ33) | BV4: θ34 | BW4: Q(θ34) | BX4: θ35 | BY4: Q(θ35) | BZ4: θ36 | CA4: Q(θ36) | CB4: θ37 | CC4: Q(θ37) | CD4: θ38 | CE4: Q(θ38) | CF4: θ39 | CG4: Q(θ39) | CH4: θ40
A5: =계산!A5 -> BC-01 | B5: =계산!E5 -> 0.0017890046 | C5: =입력!E5/1000 -> 0.2 | D5: =(입력!F5-입력!G5)/입력!D5 -> 0.013 | E5: =입력!J5 -> 0.011 | F5: =설정!$B$10/2 -> 2.6383016 | G5: =IF($D5<=0,0,($C5^2/8*(F5-SIN(F5)))*(($C5^2/8*(F5-SIN(F5)))/($C5*F5/2))^(2/3)*$D5^0.5/$E5) -> 0.013255337 | H5: =F5+IF(G5<$B5,1,-1)*설정!$B$10/2^2 -> 1.3191508 | I5: =IF($D5<=0,0,($C5^2/8*(H5-SIN(H5)))*(($C5^2/8*(H5-SIN(H5)))/($C5*H5/2))^(2/3)*$D5^0.5/$E5) -> 0.0010196454 | J5: =H5+IF(I5<$B5,1,-1)*설정!$B$10/2^3 -> 1.9787262 | K5: =IF($D5<=0,0,($C5^2/8*(J5-SIN(J5)))*(($C5^2/8*(J5-SIN(J5)))/($C5*J5/2))^(2/3)*$D5^0.5/$E5) -> 0.0049239717 | L5: =J5+IF(K5<$B5,1,-1)*설정!$B$10/2^4 -> 1.6489385 | M5: =IF($D5<=0,0,($C5^2/8*(L5-SIN(L5)))*(($C5^2/8*(L5-SIN(L5)))/($C5*L5/2))^(2/3)*$D5^0.5/$E5) -> 0.0024705537 | N5: =L5+IF(M5<$B5,1,-1)*설정!$B$10/2^5 -> 1.4840447 | O5: =IF($D5<=0,0,($C5^2/8*(N5-SIN(N5)))*(($C5^2/8*(N5-SIN(N5)))/($C5*N5/2))^(2/3)*$D5^0.5/$E5) -> 0.0016342121 | P5: =N5+IF(O5<$B5,1,-1)*설정!$B$10/2^6 -> 1.5664916 | Q5: =IF($D5<=0,0,($C5^2/8*(P5-SIN(P5)))*(($C5^2/8*(P5-SIN(P5)))/($C5*P5/2))^(2/3)*$D5^0.5/$E5) -> 0.0020226057 | R5: =P5+IF(Q5<$B5,1,-1)*설정!$B$10/2^7 -> 1.5252681 | S5: =IF($D5<=0,0,($C5^2/8*(R5-SIN(R5)))*(($C5^2/8*(R5-SIN(R5)))/($C5*R5/2))^(2/3)*$D5^0.5/$E5) -> 0.001821209 | T5: =R5+IF(S5<$B5,1,-1)*설정!$B$10/2^8 -> 1.5046564 | U5: =IF($D5<=0,0,($C5^2/8*(T5-SIN(T5)))*(($C5^2/8*(T5-SIN(T5)))/($C5*T5/2))^(2/3)*$D5^0.5/$E5) -> 0.0017259424 | V5: =T5+IF(U5<$B5,1,-1)*설정!$B$10/2^9 -> 1.5149623 | W5: =IF($D5<=0,0,($C5^2/8*(V5-SIN(V5)))*(($C5^2/8*(V5-SIN(V5)))/($C5*V5/2))^(2/3)*$D5^0.5/$E5) -> 0.0017731296 | X5: =V5+IF(W5<$B5,1,-1)*설정!$B$10/2^10 -> 1.5201152 | Y5: =IF($D5<=0,0,($C5^2/8*(X5-SIN(X5)))*(($C5^2/8*(X5-SIN(X5)))/($C5*X5/2))^(2/3)*$D5^0.5/$E5) -> 0.0017970573 | Z5: =X5+IF(Y5<$B5,1,-1)*설정!$B$10/2^11 -> 1.5175387 | AA5: =IF($D5<=0,0,($C5^2/8*(Z5-SIN(Z5)))*(($C5^2/8*(Z5-SIN(Z5)))/($C5*Z5/2))^(2/3)*$D5^0.5/$E5) -> 0.0017850655 | AB5: =Z5+IF(AA5<$B5,1,-1)*설정!$B$10/2^12 -> 1.518827 | AC5: =IF($D5<=0,0,($C5^2/8*(AB5-SIN(AB5)))*(($C5^2/8*(AB5-SIN(AB5)))/($C5*AB5/2))^(2/3)*$D5^0.5/$E5) -> 0.0017910544 | AD5: =AB5+IF(AC5<$B5,1,-1)*설정!$B$10/2^13 -> 1.5181828 | AE5: =IF($D5<=0,0,($C5^2/8*(AD5-SIN(AD5)))*(($C5^2/8*(AD5-SIN(AD5)))/($C5*AD5/2))^(2/3)*$D5^0.5/$E5) -> 0.0017880582 | AF5: =AD5+IF(AE5<$B5,1,-1)*설정!$B$10/2^14 -> 1.5185049 | AG5: =IF($D5<=0,0,($C5^2/8*(AF5-SIN(AF5)))*(($C5^2/8*(AF5-SIN(AF5)))/($C5*AF5/2))^(2/3)*$D5^0.5/$E5) -> 0.0017895559 | AH5: =AF5+IF(AG5<$B5,1,-1)*설정!$B$10/2^15 -> 1.5183439 | AI5: =IF($D5<=0,0,($C5^2/8*(AH5-SIN(AH5)))*(($C5^2/8*(AH5-SIN(AH5)))/($C5*AH5/2))^(2/3)*$D5^0.5/$E5) -> 0.001788807 | AJ5: =AH5+IF(AI5<$B5,1,-1)*설정!$B$10/2^16 -> 1.5184244 | AK5: =IF($D5<=0,0,($C5^2/8*(AJ5-SIN(AJ5)))*(($C5^2/8*(AJ5-SIN(AJ5)))/($C5*AJ5/2))^(2/3)*$D5^0.5/$E5) -> 0.0017891814 | AL5: =AJ5+IF(AK5<$B5,1,-1)*설정!$B$10/2^17 -> 1.5183841 | AM5: =IF($D5<=0,0,($C5^2/8*(AL5-SIN(AL5)))*(($C5^2/8*(AL5-SIN(AL5)))/($C5*AL5/2))^(2/3)*$D5^0.5/$E5) -> 0.0017889942 | AN5: =AL5+IF(AM5<$B5,1,-1)*설정!$B$10/2^18 -> 1.5184042 | AO5: =IF($D5<=0,0,($C5^2/8*(AN5-SIN(AN5)))*(($C5^2/8*(AN5-SIN(AN5)))/($C5*AN5/2))^(2/3)*$D5^0.5/$E5) -> 0.0017890878 | AP5: =AN5+IF(AO5<$B5,1,-1)*설정!$B$10/2^19 -> 1.5183942 | AQ5: =IF($D5<=0,0,($C5^2/8*(AP5-SIN(AP5)))*(($C5^2/8*(AP5-SIN(AP5)))/($C5*AP5/2))^(2/3)*$D5^0.5/$E5) -> 0.001789041 | AR5: =AP5+IF(AQ5<$B5,1,-1)*설정!$B$10/2^20 -> 1.5183892 | AS5: =IF($D5<=0,0,($C5^2/8*(AR5-SIN(AR5)))*(($C5^2/8*(AR5-SIN(AR5)))/($C5*AR5/2))^(2/3)*$D5^0.5/$E5) -> 0.0017890176 | AT5: =AR5+IF(AS5<$B5,1,-1)*설정!$B$10/2^21 -> 1.5183866 | AU5: =IF($D5<=0,0,($C5^2/8*(AT5-SIN(AT5)))*(($C5^2/8*(AT5-SIN(AT5)))/($C5*AT5/2))^(2/3)*$D5^0.5/$E5) -> 0.0017890059 | AV5: =AT5+IF(AU5<$B5,1,-1)*설정!$B$10/2^22 -> 1.5183854 | AW5: =IF($D5<=0,0,($C5^2/8*(AV5-SIN(AV5)))*(($C5^2/8*(AV5-SIN(AV5)))/($C5*AV5/2))^(2/3)*$D5^0.5/$E5) -> 0.001789 | AX5: =AV5+IF(AW5<$B5,1,-1)*설정!$B$10/2^23 -> 1.518386 | AY5: =IF($D5<=0,0,($C5^2/8*(AX5-SIN(AX5)))*(($C5^2/8*(AX5-SIN(AX5)))/($C5*AX5/2))^(2/3)*$D5^0.5/$E5) -> 0.001789003 | AZ5: =AX5+IF(AY5<$B5,1,-1)*설정!$B$10/2^24 -> 1.5183863 | BA5: =IF($D5<=0,0,($C5^2/8*(AZ5-SIN(AZ5)))*(($C5^2/8*(AZ5-SIN(AZ5)))/($C5*AZ5/2))^(2/3)*$D5^0.5/$E5) -> 0.0017890044 | BB5: =AZ5+IF(BA5<$B5,1,-1)*설정!$B$10/2^25 -> 1.5183865 | BC5: =IF($D5<=0,0,($C5^2/8*(BB5-SIN(BB5)))*(($C5^2/8*(BB5-SIN(BB5)))/($C5*BB5/2))^(2/3)*$D5^0.5/$E5) -> 0.0017890051 | BD5: =BB5+IF(BC5<$B5,1,-1)*설정!$B$10/2^26 -> 1.5183864 | BE5: =IF($D5<=0,0,($C5^2/8*(BD5-SIN(BD5)))*(($C5^2/8*(BD5-SIN(BD5)))/($C5*BD5/2))^(2/3)*$D5^0.5/$E5) -> 0.0017890048 | BF5: =BD5+IF(BE5<$B5,1,-1)*설정!$B$10/2^27 -> 1.5183864 | BG5: =IF($D5<=0,0,($C5^2/8*(BF5-SIN(BF5)))*(($C5^2/8*(BF5-SIN(BF5)))/($C5*BF5/2))^(2/3)*$D5^0.5/$E5) -> 0.0017890046 | BH5: =BF5+IF(BG5<$B5,1,-1)*설정!$B$10/2^28 -> 1.5183864 | BI5: =IF($D5<=0,0,($C5^2/8*(BH5-SIN(BH5)))*(($C5^2/8*(BH5-SIN(BH5)))/($C5*BH5/2))^(2/3)*$D5^0.5/$E5) -> 0.0017890047 | BJ5: =BH5+IF(BI5<$B5,1,-1)*설정!$B$10/2^29 -> 1.5183864 | BK5: =IF($D5<=0,0,($C5^2/8*(BJ5-SIN(BJ5)))*(($C5^2/8*(BJ5-SIN(BJ5)))/($C5*BJ5/2))^(2/3)*$D5^0.5/$E5) -> 0.0017890046 | BL5: =BJ5+IF(BK5<$B5,1,-1)*설정!$B$10/2^30 -> 1.5183864 | BM5: =IF($D5<=0,0,($C5^2/8*(BL5-SIN(BL5)))*(($C5^2/8*(BL5-SIN(BL5)))/($C5*BL5/2))^(2/3)*$D5^0.5/$E5) -> 0.0017890046 | BN5: =BL5+IF(BM5<$B5,1,-1)*설정!$B$10/2^31 -> 1.5183864 | BO5: =IF($D5<=0,0,($C5^2/8*(BN5-SIN(BN5)))*(($C5^2/8*(BN5-SIN(BN5)))/($C5*BN5/2))^(2/3)*$D5^0.5/$E5) -> 0.0017890046 | BP5: =BN5+IF(BO5<$B5,1,-1)*설정!$B$10/2^32 -> 1.5183864 | BQ5: =IF($D5<=0,0,($C5^2/8*(BP5-SIN(BP5)))*(($C5^2/8*(BP5-SIN(BP5)))/($C5*BP5/2))^(2/3)*$D5^0.5/$E5) -> 0.0017890046 | BR5: =BP5+IF(BQ5<$B5,1,-1)*설정!$B$10/2^33 -> 1.5183864 | BS5: =IF($D5<=0,0,($C5^2/8*(BR5-SIN(BR5)))*(($C5^2/8*(BR5-SIN(BR5)))/($C5*BR5/2))^(2/3)*$D5^0.5/$E5) -> 0.0017890046 | BT5: =BR5+IF(BS5<$B5,1,-1)*설정!$B$10/2^34 -> 1.5183864 | BU5: =IF($D5<=0,0,($C5^2/8*(BT5-SIN(BT5)))*(($C5^2/8*(BT5-SIN(BT5)))/($C5*BT5/2))^(2/3)*$D5^0.5/$E5) -> 0.0017890046 | BV5: =BT5+IF(BU5<$B5,1,-1)*설정!$B$10/2^35 -> 1.5183864 | BW5: =IF($D5<=0,0,($C5^2/8*(BV5-SIN(BV5)))*(($C5^2/8*(BV5-SIN(BV5)))/($C5*BV5/2))^(2/3)*$D5^0.5/$E5) -> 0.0017890046 | BX5: =BV5+IF(BW5<$B5,1,-1)*설정!$B$10/2^36 -> 1.5183864 | BY5: =IF($D5<=0,0,($C5^2/8*(BX5-SIN(BX5)))*(($C5^2/8*(BX5-SIN(BX5)))/($C5*BX5/2))^(2/3)*$D5^0.5/$E5) -> 0.0017890046 | BZ5: =BX5+IF(BY5<$B5,1,-1)*설정!$B$10/2^37 -> 1.5183864 | CA5: =IF($D5<=0,0,($C5^2/8*(BZ5-SIN(BZ5)))*(($C5^2/8*(BZ5-SIN(BZ5)))/($C5*BZ5/2))^(2/3)*$D5^0.5/$E5) -> 0.0017890046 | CB5: =BZ5+IF(CA5<$B5,1,-1)*설정!$B$10/2^38 -> 1.5183864 | CC5: =IF($D5<=0,0,($C5^2/8*(CB5-SIN(CB5)))*(($C5^2/8*(CB5-SIN(CB5)))/($C5*CB5/2))^(2/3)*$D5^0.5/$E5) -> 0.0017890046 | CD5: =CB5+IF(CC5<$B5,1,-1)*설정!$B$10/2^39 -> 1.5183864 | CE5: =IF($D5<=0,0,($C5^2/8*(CD5-SIN(CD5)))*(($C5^2/8*(CD5-SIN(CD5)))/($C5*CD5/2))^(2/3)*$D5^0.5/$E5) -> 0.0017890046 | CF5: =CD5+IF(CE5<$B5,1,-1)*설정!$B$10/2^40 -> 1.5183864 | CG5: =IF($D5<=0,0,($C5^2/8*(CF5-SIN(CF5)))*(($C5^2/8*(CF5-SIN(CF5)))/($C5*CF5/2))^(2/3)*$D5^0.5/$E5) -> 0.0017890046 | CH5: =CF5+IF(CG5<$B5,1,-1)*설정!$B$10/2^41 -> 1.5183864
A6: =계산!A6 -> BC-02 | B6: =계산!E6 -> 0.0017890046 | C6: =입력!E6/1000 -> 0.2 | D6: =(입력!F6-입력!G6)/입력!D6 -> 0.0114 | E6: =입력!J6 -> 0.011 | F6: =설정!$B$10/2 -> 2.6383016 | G6: =IF($D6<=0,0,($C6^2/8*(F6-SIN(F6)))*(($C6^2/8*(F6-SIN(F6)))/($C6*F6/2))^(2/3)*$D6^0.5/$E6) -> 0.012412851 | H6: =F6+IF(G6<$B6,1,-1)*설정!$B$10/2^2 -> 1.3191508 | I6: =IF($D6<=0,0,($C6^2/8*(H6-SIN(H6)))*(($C6^2/8*(H6-SIN(H6)))/($C6*H6/2))^(2/3)*$D6^0.5/$E6) -> 0.0009548385 | J6: =H6+IF(I6<$B6,1,-1)*설정!$B$10/2^3 -> 1.9787262 | K6: =IF($D6<=0,0,($C6^2/8*(J6-SIN(J6)))*(($C6^2/8*(J6-SIN(J6)))/($C6*J6/2))^(2/3)*$D6^0.5/$E6) -> 0.0046110125 | L6: =J6+IF(K6<$B6,1,-1)*설정!$B$10/2^4 -> 1.6489385 | M6: =IF($D6<=0,0,($C6^2/8*(L6-SIN(L6)))*(($C6^2/8*(L6-SIN(L6)))/($C6*L6/2))^(2/3)*$D6^0.5/$E6) -> 0.0023135296 | N6: =L6+IF(M6<$B6,1,-1)*설정!$B$10/2^5 -> 1.4840447 | O6: =IF($D6<=0,0,($C6^2/8*(N6-SIN(N6)))*(($C6^2/8*(N6-SIN(N6)))/($C6*N6/2))^(2/3)*$D6^0.5/$E6) -> 0.0015303444 | P6: =N6+IF(O6<$B6,1,-1)*설정!$B$10/2^6 -> 1.5664916 | Q6: =IF($D6<=0,0,($C6^2/8*(P6-SIN(P6)))*(($C6^2/8*(P6-SIN(P6)))/($C6*P6/2))^(2/3)*$D6^0.5/$E6) -> 0.0018940523 | R6: =P6+IF(Q6<$B6,1,-1)*설정!$B$10/2^7 -> 1.5252681 | S6: =IF($D6<=0,0,($C6^2/8*(R6-SIN(R6)))*(($C6^2/8*(R6-SIN(R6)))/($C6*R6/2))^(2/3)*$D6^0.5/$E6) -> 0.0017054561 | T6: =R6+IF(S6<$B6,1,-1)*설정!$B$10/2^8 -> 1.5458798 | U6: =IF($D6<=0,0,($C6^2/8*(T6-SIN(T6)))*(($C6^2/8*(T6-SIN(T6)))/($C6*T6/2))^(2/3)*$D6^0.5/$E6) -> 0.0017980392 | V6: =T6+IF(U6<$B6,1,-1)*설정!$B$10/2^9 -> 1.535574 | W6: =IF($D6<=0,0,($C6^2/8*(V6-SIN(V6)))*(($C6^2/8*(V6-SIN(V6)))/($C6*V6/2))^(2/3)*$D6^0.5/$E6) -> 0.0017513225 | X6: =V6+IF(W6<$B6,1,-1)*설정!$B$10/2^10 -> 1.5407269 | Y6: =IF($D6<=0,0,($C6^2/8*(X6-SIN(X6)))*(($C6^2/8*(X6-SIN(X6)))/($C6*X6/2))^(2/3)*$D6^0.5/$E6) -> 0.0017745741 | Z6: =X6+IF(Y6<$B6,1,-1)*설정!$B$10/2^11 -> 1.5433034 | AA6: =IF($D6<=0,0,($C6^2/8*(Z6-SIN(Z6)))*(($C6^2/8*(Z6-SIN(Z6)))/($C6*Z6/2))^(2/3)*$D6^0.5/$E6) -> 0.0017862799 | AB6: =Z6+IF(AA6<$B6,1,-1)*설정!$B$10/2^12 -> 1.5445916 | AC6: =IF($D6<=0,0,($C6^2/8*(AB6-SIN(AB6)))*(($C6^2/8*(AB6-SIN(AB6)))/($C6*AB6/2))^(2/3)*$D6^0.5/$E6) -> 0.0017921529 | AD6: =AB6+IF(AC6<$B6,1,-1)*설정!$B$10/2^13 -> 1.5439475 | AE6: =IF($D6<=0,0,($C6^2/8*(AD6-SIN(AD6)))*(($C6^2/8*(AD6-SIN(AD6)))/($C6*AD6/2))^(2/3)*$D6^0.5/$E6) -> 0.0017892147 | AF6: =AD6+IF(AE6<$B6,1,-1)*설정!$B$10/2^14 -> 1.5436254 | AG6: =IF($D6<=0,0,($C6^2/8*(AF6-SIN(AF6)))*(($C6^2/8*(AF6-SIN(AF6)))/($C6*AF6/2))^(2/3)*$D6^0.5/$E6) -> 0.0017877469 | AH6: =AF6+IF(AG6<$B6,1,-1)*설정!$B$10/2^15 -> 1.5437865 | AI6: =IF($D6<=0,0,($C6^2/8*(AH6-SIN(AH6)))*(($C6^2/8*(AH6-SIN(AH6)))/($C6*AH6/2))^(2/3)*$D6^0.5/$E6) -> 0.0017884807 | AJ6: =AH6+IF(AI6<$B6,1,-1)*설정!$B$10/2^16 -> 1.543867 | AK6: =IF($D6<=0,0,($C6^2/8*(AJ6-SIN(AJ6)))*(($C6^2/8*(AJ6-SIN(AJ6)))/($C6*AJ6/2))^(2/3)*$D6^0.5/$E6) -> 0.0017888477 | AL6: =AJ6+IF(AK6<$B6,1,-1)*설정!$B$10/2^17 -> 1.5439072 | AM6: =IF($D6<=0,0,($C6^2/8*(AL6-SIN(AL6)))*(($C6^2/8*(AL6-SIN(AL6)))/($C6*AL6/2))^(2/3)*$D6^0.5/$E6) -> 0.0017890312 | AN6: =AL6+IF(AM6<$B6,1,-1)*설정!$B$10/2^18 -> 1.5438871 | AO6: =IF($D6<=0,0,($C6^2/8*(AN6-SIN(AN6)))*(($C6^2/8*(AN6-SIN(AN6)))/($C6*AN6/2))^(2/3)*$D6^0.5/$E6) -> 0.0017889395 | AP6: =AN6+IF(AO6<$B6,1,-1)*설정!$B$10/2^19 -> 1.5438972 | AQ6: =IF($D6<=0,0,($C6^2/8*(AP6-SIN(AP6)))*(($C6^2/8*(AP6-SIN(AP6)))/($C6*AP6/2))^(2/3)*$D6^0.5/$E6) -> 0.0017889853 | AR6: =AP6+IF(AQ6<$B6,1,-1)*설정!$B$10/2^20 -> 1.5439022 | AS6: =IF($D6<=0,0,($C6^2/8*(AR6-SIN(AR6)))*(($C6^2/8*(AR6-SIN(AR6)))/($C6*AR6/2))^(2/3)*$D6^0.5/$E6) -> 0.0017890083 | AT6: =AR6+IF(AS6<$B6,1,-1)*설정!$B$10/2^21 -> 1.5438997 | AU6: =IF($D6<=0,0,($C6^2/8*(AT6-SIN(AT6)))*(($C6^2/8*(AT6-SIN(AT6)))/($C6*AT6/2))^(2/3)*$D6^0.5/$E6) -> 0.0017889968 | AV6: =AT6+IF(AU6<$B6,1,-1)*설정!$B$10/2^22 -> 1.543901 | AW6: =IF($D6<=0,0,($C6^2/8*(AV6-SIN(AV6)))*(($C6^2/8*(AV6-SIN(AV6)))/($C6*AV6/2))^(2/3)*$D6^0.5/$E6) -> 0.0017890025 | AX6: =AV6+IF(AW6<$B6,1,-1)*설정!$B$10/2^23 -> 1.5439016 | AY6: =IF($D6<=0,0,($C6^2/8*(AX6-SIN(AX6)))*(($C6^2/8*(AX6-SIN(AX6)))/($C6*AX6/2))^(2/3)*$D6^0.5/$E6) -> 0.0017890054 | AZ6: =AX6+IF(AY6<$B6,1,-1)*설정!$B$10/2^24 -> 1.5439013 | BA6: =IF($D6<=0,0,($C6^2/8*(AZ6-SIN(AZ6)))*(($C6^2/8*(AZ6-SIN(AZ6)))/($C6*AZ6/2))^(2/3)*$D6^0.5/$E6) -> 0.001789004 | BB6: =AZ6+IF(BA6<$B6,1,-1)*설정!$B$10/2^25 -> 1.5439014 | BC6: =IF($D6<=0,0,($C6^2/8*(BB6-SIN(BB6)))*(($C6^2/8*(BB6-SIN(BB6)))/($C6*BB6/2))^(2/3)*$D6^0.5/$E6) -> 0.0017890047 | BD6: =BB6+IF(BC6<$B6,1,-1)*설정!$B$10/2^26 -> 1.5439013 | BE6: =IF($D6<=0,0,($C6^2/8*(BD6-SIN(BD6)))*(($C6^2/8*(BD6-SIN(BD6)))/($C6*BD6/2))^(2/3)*$D6^0.5/$E6) -> 0.0017890043 | BF6: =BD6+IF(BE6<$B6,1,-1)*설정!$B$10/2^27 -> 1.5439014 | BG6: =IF($D6<=0,0,($C6^2/8*(BF6-SIN(BF6)))*(($C6^2/8*(BF6-SIN(BF6)))/($C6*BF6/2))^(2/3)*$D6^0.5/$E6) -> 0.0017890045 | BH6: =BF6+IF(BG6<$B6,1,-1)*설정!$B$10/2^28 -> 1.5439014 | BI6: =IF($D6<=0,0,($C6^2/8*(BH6-SIN(BH6)))*(($C6^2/8*(BH6-SIN(BH6)))/($C6*BH6/2))^(2/3)*$D6^0.5/$E6) -> 0.0017890046 | BJ6: =BH6+IF(BI6<$B6,1,-1)*설정!$B$10/2^29 -> 1.5439014 | BK6: =IF($D6<=0,0,($C6^2/8*(BJ6-SIN(BJ6)))*(($C6^2/8*(BJ6-SIN(BJ6)))/($C6*BJ6/2))^(2/3)*$D6^0.5/$E6) -> 0.0017890046 | BL6: =BJ6+IF(BK6<$B6,1,-1)*설정!$B$10/2^30 -> 1.5439014 | BM6: =IF($D6<=0,0,($C6^2/8*(BL6-SIN(BL6)))*(($C6^2/8*(BL6-SIN(BL6)))/($C6*BL6/2))^(2/3)*$D6^0.5/$E6) -> 0.0017890046 | BN6: =BL6+IF(BM6<$B6,1,-1)*설정!$B$10/2^31 -> 1.5439014 | BO6: =IF($D6<=0,0,($C6^2/8*(BN6-SIN(BN6)))*(($C6^2/8*(BN6-SIN(BN6)))/($C6*BN6/2))^(2/3)*$D6^0.5/$E6) -> 0.0017890046 | BP6: =BN6+IF(BO6<$B6,1,-1)*설정!$B$10/2^32 -> 1.5439014 | BQ6: =IF($D6<=0,0,($C6^2/8*(BP6-SIN(BP6)))*(($C6^2/8*(BP6-SIN(BP6)))/($C6*BP6/2))^(2/3)*$D6^0.5/$E6) -> 0.0017890046 | BR6: =BP6+IF(BQ6<$B6,1,-1)*설정!$B$10/2^33 -> 1.5439014 | BS6: =IF($D6<=0,0,($C6^2/8*(BR6-SIN(BR6)))*(($C6^2/8*(BR6-SIN(BR6)))/($C6*BR6/2))^(2/3)*$D6^0.5/$E6) -> 0.0017890046 | BT6: =BR6+IF(BS6<$B6,1,-1)*설정!$B$10/2^34 -> 1.5439014 | BU6: =IF($D6<=0,0,($C6^2/8*(BT6-SIN(BT6)))*(($C6^2/8*(BT6-SIN(BT6)))/($C6*BT6/2))^(2/3)*$D6^0.5/$E6) -> 0.0017890046 | BV6: =BT6+IF(BU6<$B6,1,-1)*설정!$B$10/2^35 -> 1.5439014 | BW6: =IF($D6<=0,0,($C6^2/8*(BV6-SIN(BV6)))*(($C6^2/8*(BV6-SIN(BV6)))/($C6*BV6/2))^(2/3)*$D6^0.5/$E6) -> 0.0017890046 | BX6: =BV6+IF(BW6<$B6,1,-1)*설정!$B$10/2^36 -> 1.5439014 | BY6: =IF($D6<=0,0,($C6^2/8*(BX6-SIN(BX6)))*(($C6^2/8*(BX6-SIN(BX6)))/($C6*BX6/2))^(2/3)*$D6^0.5/$E6) -> 0.0017890046 | BZ6: =BX6+IF(BY6<$B6,1,-1)*설정!$B$10/2^37 -> 1.5439014 | CA6: =IF($D6<=0,0,($C6^2/8*(BZ6-SIN(BZ6)))*(($C6^2/8*(BZ6-SIN(BZ6)))/($C6*BZ6/2))^(2/3)*$D6^0.5/$E6) -> 0.0017890046 | CB6: =BZ6+IF(CA6<$B6,1,-1)*설정!$B$10/2^38 -> 1.5439014 | CC6: =IF($D6<=0,0,($C6^2/8*(CB6-SIN(CB6)))*(($C6^2/8*(CB6-SIN(CB6)))/($C6*CB6/2))^(2/3)*$D6^0.5/$E6) -> 0.0017890046 | CD6: =CB6+IF(CC6<$B6,1,-1)*설정!$B$10/2^39 -> 1.5439014 | CE6: =IF($D6<=0,0,($C6^2/8*(CD6-SIN(CD6)))*(($C6^2/8*(CD6-SIN(CD6)))/($C6*CD6/2))^(2/3)*$D6^0.5/$E6) -> 0.0017890046 | CF6: =CD6+IF(CE6<$B6,1,-1)*설정!$B$10/2^40 -> 1.5439014 | CG6: =IF($D6<=0,0,($C6^2/8*(CF6-SIN(CF6)))*(($C6^2/8*(CF6-SIN(CF6)))/($C6*CF6/2))^(2/3)*$D6^0.5/$E6) -> 0.0017890046 | CH6: =CF6+IF(CG6<$B6,1,-1)*설정!$B$10/2^41 -> 1.5439014
A7: =계산!A7 -> BC-03 | B7: =계산!E7 -> 0.0017890046 | C7: =입력!E7/1000 -> 0.2 | D7: =(입력!F7-입력!G7)/입력!D7 -> 0.0192 | E7: =입력!J7 -> 0.011 | F7: =설정!$B$10/2 -> 2.6383016 | G7: =IF($D7<=0,0,($C7^2/8*(F7-SIN(F7)))*(($C7^2/8*(F7-SIN(F7)))/($C7*F7/2))^(2/3)*$D7^0.5/$E7) -> 0.016109042 | H7: =F7+IF(G7<$B7,1,-1)*설정!$B$10/2^2 -> 1.3191508 | I7: =IF($D7<=0,0,($C7^2/8*(H7-SIN(H7)))*(($C7^2/8*(H7-SIN(H7)))/($C7*H7/2))^(2/3)*$D7^0.5/$E7) -> 0.0012391621 | J7: =H7+IF(I7<$B7,1,-1)*설정!$B$10/2^3 -> 1.9787262 | K7: =IF($D7<=0,0,($C7^2/8*(J7-SIN(J7)))*(($C7^2/8*(J7-SIN(J7)))/($C7*J7/2))^(2/3)*$D7^0.5/$E7) -> 0.00598404 | L7: =J7+IF(K7<$B7,1,-1)*설정!$B$10/2^4 -> 1.6489385 | M7: =IF($D7<=0,0,($C7^2/8*(L7-SIN(L7)))*(($C7^2/8*(L7-SIN(L7)))/($C7*L7/2))^(2/3)*$D7^0.5/$E7) -> 0.0030024324 | N7: =L7+IF(M7<$B7,1,-1)*설정!$B$10/2^5 -> 1.4840447 | O7: =IF($D7<=0,0,($C7^2/8*(N7-SIN(N7)))*(($C7^2/8*(N7-SIN(N7)))/($C7*N7/2))^(2/3)*$D7^0.5/$E7) -> 0.0019860371 | P7: =N7+IF(O7<$B7,1,-1)*설정!$B$10/2^6 -> 1.4015977 | Q7: =IF($D7<=0,0,($C7^2/8*(P7-SIN(P7)))*(($C7^2/8*(P7-SIN(P7)))/($C7*P7/2))^(2/3)*$D7^0.5/$E7) -> 0.0015814971 | R7: =P7+IF(Q7<$B7,1,-1)*설정!$B$10/2^7 -> 1.4428212 | S7: =IF($D7<=0,0,($C7^2/8*(R7-SIN(R7)))*(($C7^2/8*(R7-SIN(R7)))/($C7*R7/2))^(2/3)*$D7^0.5/$E7) -> 0.0017756552 | T7: =R7+IF(S7<$B7,1,-1)*설정!$B$10/2^8 -> 1.4634329 | U7: =IF($D7<=0,0,($C7^2/8*(T7-SIN(T7)))*(($C7^2/8*(T7-SIN(T7)))/($C7*T7/2))^(2/3)*$D7^0.5/$E7) -> 0.0018787771 | V7: =T7+IF(U7<$B7,1,-1)*설정!$B$10/2^9 -> 1.4531271 | W7: =IF($D7<=0,0,($C7^2/8*(V7-SIN(V7)))*(($C7^2/8*(V7-SIN(V7)))/($C7*V7/2))^(2/3)*$D7^0.5/$E7) -> 0.001826704 | X7: =V7+IF(W7<$B7,1,-1)*설정!$B$10/2^10 -> 1.4479741 | Y7: =IF($D7<=0,0,($C7^2/8*(X7-SIN(X7)))*(($C7^2/8*(X7-SIN(X7)))/($C7*X7/2))^(2/3)*$D7^0.5/$E7) -> 0.0018010522 | Z7: =X7+IF(Y7<$B7,1,-1)*설정!$B$10/2^11 -> 1.4453977 | AA7: =IF($D7<=0,0,($C7^2/8*(Z7-SIN(Z7)))*(($C7^2/8*(Z7-SIN(Z7)))/($C7*Z7/2))^(2/3)*$D7^0.5/$E7) -> 0.0017883219 | AB7: =Z7+IF(AA7<$B7,1,-1)*설정!$B$10/2^12 -> 1.4466859 | AC7: =IF($D7<=0,0,($C7^2/8*(AB7-SIN(AB7)))*(($C7^2/8*(AB7-SIN(AB7)))/($C7*AB7/2))^(2/3)*$D7^0.5/$E7) -> 0.0017946791 | AD7: =AB7+IF(AC7<$B7,1,-1)*설정!$B$10/2^13 -> 1.4460418 | AE7: =IF($D7<=0,0,($C7^2/8*(AD7-SIN(AD7)))*(($C7^2/8*(AD7-SIN(AD7)))/($C7*AD7/2))^(2/3)*$D7^0.5/$E7) -> 0.0017914985 | AF7: =AD7+IF(AE7<$B7,1,-1)*설정!$B$10/2^14 -> 1.4457197 | AG7: =IF($D7<=0,0,($C7^2/8*(AF7-SIN(AF7)))*(($C7^2/8*(AF7-SIN(AF7)))/($C7*AF7/2))^(2/3)*$D7^0.5/$E7) -> 0.0017899097 | AH7: =AF7+IF(AG7<$B7,1,-1)*설정!$B$10/2^15 -> 1.4455587 | AI7: =IF($D7<=0,0,($C7^2/8*(AH7-SIN(AH7)))*(($C7^2/8*(AH7-SIN(AH7)))/($C7*AH7/2))^(2/3)*$D7^0.5/$E7) -> 0.0017891157 | AJ7: =AH7+IF(AI7<$B7,1,-1)*설정!$B$10/2^16 -> 1.4454782 | AK7: =IF($D7<=0,0,($C7^2/8*(AJ7-SIN(AJ7)))*(($C7^2/8*(AJ7-SIN(AJ7)))/($C7*AJ7/2))^(2/3)*$D7^0.5/$E7) -> 0.0017887188 | AL7: =AJ7+IF(AK7<$B7,1,-1)*설정!$B$10/2^17 -> 1.4455184 | AM7: =IF($D7<=0,0,($C7^2/8*(AL7-SIN(AL7)))*(($C7^2/8*(AL7-SIN(AL7)))/($C7*AL7/2))^(2/3)*$D7^0.5/$E7) -> 0.0017889172 | AN7: =AL7+IF(AM7<$B7,1,-1)*설정!$B$10/2^18 -> 1.4455386 | AO7: =IF($D7<=0,0,($C7^2/8*(AN7-SIN(AN7)))*(($C7^2/8*(AN7-SIN(AN7)))/($C7*AN7/2))^(2/3)*$D7^0.5/$E7) -> 0.0017890165 | AP7: =AN7+IF(AO7<$B7,1,-1)*설정!$B$10/2^19 -> 1.4455285 | AQ7: =IF($D7<=0,0,($C7^2/8*(AP7-SIN(AP7)))*(($C7^2/8*(AP7-SIN(AP7)))/($C7*AP7/2))^(2/3)*$D7^0.5/$E7) -> 0.0017889668 | AR7: =AP7+IF(AQ7<$B7,1,-1)*설정!$B$10/2^20 -> 1.4455335 | AS7: =IF($D7<=0,0,($C7^2/8*(AR7-SIN(AR7)))*(($C7^2/8*(AR7-SIN(AR7)))/($C7*AR7/2))^(2/3)*$D7^0.5/$E7) -> 0.0017889916 | AT7: =AR7+IF(AS7<$B7,1,-1)*설정!$B$10/2^21 -> 1.445536 | AU7: =IF($D7<=0,0,($C7^2/8*(AT7-SIN(AT7)))*(($C7^2/8*(AT7-SIN(AT7)))/($C7*AT7/2))^(2/3)*$D7^0.5/$E7) -> 0.001789004 | AV7: =AT7+IF(AU7<$B7,1,-1)*설정!$B$10/2^22 -> 1.4455373 | AW7: =IF($D7<=0,0,($C7^2/8*(AV7-SIN(AV7)))*(($C7^2/8*(AV7-SIN(AV7)))/($C7*AV7/2))^(2/3)*$D7^0.5/$E7) -> 0.0017890103 | AX7: =AV7+IF(AW7<$B7,1,-1)*설정!$B$10/2^23 -> 1.4455367 | AY7: =IF($D7<=0,0,($C7^2/8*(AX7-SIN(AX7)))*(($C7^2/8*(AX7-SIN(AX7)))/($C7*AX7/2))^(2/3)*$D7^0.5/$E7) -> 0.0017890071 | AZ7: =AX7+IF(AY7<$B7,1,-1)*설정!$B$10/2^24 -> 1.4455364 | BA7: =IF($D7<=0,0,($C7^2/8*(AZ7-SIN(AZ7)))*(($C7^2/8*(AZ7-SIN(AZ7)))/($C7*AZ7/2))^(2/3)*$D7^0.5/$E7) -> 0.0017890056 | BB7: =AZ7+IF(BA7<$B7,1,-1)*설정!$B$10/2^25 -> 1.4455362 | BC7: =IF($D7<=0,0,($C7^2/8*(BB7-SIN(BB7)))*(($C7^2/8*(BB7-SIN(BB7)))/($C7*BB7/2))^(2/3)*$D7^0.5/$E7) -> 0.0017890048 | BD7: =BB7+IF(BC7<$B7,1,-1)*설정!$B$10/2^26 -> 1.4455361 | BE7: =IF($D7<=0,0,($C7^2/8*(BD7-SIN(BD7)))*(($C7^2/8*(BD7-SIN(BD7)))/($C7*BD7/2))^(2/3)*$D7^0.5/$E7) -> 0.0017890044 | BF7: =BD7+IF(BE7<$B7,1,-1)*설정!$B$10/2^27 -> 1.4455362 | BG7: =IF($D7<=0,0,($C7^2/8*(BF7-SIN(BF7)))*(($C7^2/8*(BF7-SIN(BF7)))/($C7*BF7/2))^(2/3)*$D7^0.5/$E7) -> 0.0017890046 | BH7: =BF7+IF(BG7<$B7,1,-1)*설정!$B$10/2^28 -> 1.4455362 | BI7: =IF($D7<=0,0,($C7^2/8*(BH7-SIN(BH7)))*(($C7^2/8*(BH7-SIN(BH7)))/($C7*BH7/2))^(2/3)*$D7^0.5/$E7) -> 0.0017890047 | BJ7: =BH7+IF(BI7<$B7,1,-1)*설정!$B$10/2^29 -> 1.4455362 | BK7: =IF($D7<=0,0,($C7^2/8*(BJ7-SIN(BJ7)))*(($C7^2/8*(BJ7-SIN(BJ7)))/($C7*BJ7/2))^(2/3)*$D7^0.5/$E7) -> 0.0017890047 | BL7: =BJ7+IF(BK7<$B7,1,-1)*설정!$B$10/2^30 -> 1.4455362 | BM7: =IF($D7<=0,0,($C7^2/8*(BL7-SIN(BL7)))*(($C7^2/8*(BL7-SIN(BL7)))/($C7*BL7/2))^(2/3)*$D7^0.5/$E7) -> 0.0017890047 | BN7: =BL7+IF(BM7<$B7,1,-1)*설정!$B$10/2^31 -> 1.4455362 | BO7: =IF($D7<=0,0,($C7^2/8*(BN7-SIN(BN7)))*(($C7^2/8*(BN7-SIN(BN7)))/($C7*BN7/2))^(2/3)*$D7^0.5/$E7) -> 0.0017890046 | BP7: =BN7+IF(BO7<$B7,1,-1)*설정!$B$10/2^32 -> 1.4455362 | BQ7: =IF($D7<=0,0,($C7^2/8*(BP7-SIN(BP7)))*(($C7^2/8*(BP7-SIN(BP7)))/($C7*BP7/2))^(2/3)*$D7^0.5/$E7) -> 0.0017890046 | BR7: =BP7+IF(BQ7<$B7,1,-1)*설정!$B$10/2^33 -> 1.4455362 | BS7: =IF($D7<=0,0,($C7^2/8*(BR7-SIN(BR7)))*(($C7^2/8*(BR7-SIN(BR7)))/($C7*BR7/2))^(2/3)*$D7^0.5/$E7) -> 0.0017890046 | BT7: =BR7+IF(BS7<$B7,1,-1)*설정!$B$10/2^34 -> 1.4455362 | BU7: =IF($D7<=0,0,($C7^2/8*(BT7-SIN(BT7)))*(($C7^2/8*(BT7-SIN(BT7)))/($C7*BT7/2))^(2/3)*$D7^0.5/$E7) -> 0.0017890046 | BV7: =BT7+IF(BU7<$B7,1,-1)*설정!$B$10/2^35 -> 1.4455362 | BW7: =IF($D7<=0,0,($C7^2/8*(BV7-SIN(BV7)))*(($C7^2/8*(BV7-SIN(BV7)))/($C7*BV7/2))^(2/3)*$D7^0.5/$E7) -> 0.0017890046 | BX7: =BV7+IF(BW7<$B7,1,-1)*설정!$B$10/2^36 -> 1.4455362 | BY7: =IF($D7<=0,0,($C7^2/8*(BX7-SIN(BX7)))*(($C7^2/8*(BX7-SIN(BX7)))/($C7*BX7/2))^(2/3)*$D7^0.5/$E7) -> 0.0017890046 | BZ7: =BX7+IF(BY7<$B7,1,-1)*설정!$B$10/2^37 -> 1.4455362 | CA7: =IF($D7<=0,0,($C7^2/8*(BZ7-SIN(BZ7)))*(($C7^2/8*(BZ7-SIN(BZ7)))/($C7*BZ7/2))^(2/3)*$D7^0.5/$E7) -> 0.0017890046 | CB7: =BZ7+IF(CA7<$B7,1,-1)*설정!$B$10/2^38 -> 1.4455362 | CC7: =IF($D7<=0,0,($C7^2/8*(CB7-SIN(CB7)))*(($C7^2/8*(CB7-SIN(CB7)))/($C7*CB7/2))^(2/3)*$D7^0.5/$E7) -> 0.0017890046 | CD7: =CB7+IF(CC7<$B7,1,-1)*설정!$B$10/2^39 -> 1.4455362 | CE7: =IF($D7<=0,0,($C7^2/8*(CD7-SIN(CD7)))*(($C7^2/8*(CD7-SIN(CD7)))/($C7*CD7/2))^(2/3)*$D7^0.5/$E7) -> 0.0017890046 | CF7: =CD7+IF(CE7<$B7,1,-1)*설정!$B$10/2^40 -> 1.4455362 | CG7: =IF($D7<=0,0,($C7^2/8*(CF7-SIN(CF7)))*(($C7^2/8*(CF7-SIN(CF7)))/($C7*CF7/2))^(2/3)*$D7^0.5/$E7) -> 0.0017890046 | CH7: =CF7+IF(CG7<$B7,1,-1)*설정!$B$10/2^41 -> 1.4455362
A8: =계산!A8 -> BC-04 | B8: =계산!E8 -> 0.0017890046 | C8: =입력!E8/1000 -> 0.2 | D8: =(입력!F8-입력!G8)/입력!D8 -> 0.0242 | E8: =입력!J8 -> 0.011 | F8: =설정!$B$10/2 -> 2.6383016 | G8: =IF($D8<=0,0,($C8^2/8*(F8-SIN(F8)))*(($C8^2/8*(F8-SIN(F8)))/($C8*F8/2))^(2/3)*$D8^0.5/$E8) -> 0.018085344 | H8: =F8+IF(G8<$B8,1,-1)*설정!$B$10/2^2 -> 1.3191508 | I8: =IF($D8<=0,0,($C8^2/8*(H8-SIN(H8)))*(($C8^2/8*(H8-SIN(H8)))/($C8*H8/2))^(2/3)*$D8^0.5/$E8) -> 0.0013911859 | J8: =H8+IF(I8<$B8,1,-1)*설정!$B$10/2^3 -> 1.9787262 | K8: =IF($D8<=0,0,($C8^2/8*(J8-SIN(J8)))*(($C8^2/8*(J8-SIN(J8)))/($C8*J8/2))^(2/3)*$D8^0.5/$E8) -> 0.0067181788 | L8: =J8+IF(K8<$B8,1,-1)*설정!$B$10/2^4 -> 1.6489385 | M8: =IF($D8<=0,0,($C8^2/8*(L8-SIN(L8)))*(($C8^2/8*(L8-SIN(L8)))/($C8*L8/2))^(2/3)*$D8^0.5/$E8) -> 0.0033707793 | N8: =L8+IF(M8<$B8,1,-1)*설정!$B$10/2^5 -> 1.4840447 | O8: =IF($D8<=0,0,($C8^2/8*(N8-SIN(N8)))*(($C8^2/8*(N8-SIN(N8)))/($C8*N8/2))^(2/3)*$D8^0.5/$E8) -> 0.0022296897 | P8: =N8+IF(O8<$B8,1,-1)*설정!$B$10/2^6 -> 1.4015977 | Q8: =IF($D8<=0,0,($C8^2/8*(P8-SIN(P8)))*(($C8^2/8*(P8-SIN(P8)))/($C8*P8/2))^(2/3)*$D8^0.5/$E8) -> 0.0017755196 | R8: =P8+IF(Q8<$B8,1,-1)*설정!$B$10/2^7 -> 1.4428212 | S8: =IF($D8<=0,0,($C8^2/8*(R8-SIN(R8)))*(($C8^2/8*(R8-SIN(R8)))/($C8*R8/2))^(2/3)*$D8^0.5/$E8) -> 0.0019934975 | T8: =R8+IF(S8<$B8,1,-1)*설정!$B$10/2^8 -> 1.4222095 | U8: =IF($D8<=0,0,($C8^2/8*(T8-SIN(T8)))*(($C8^2/8*(T8-SIN(T8)))/($C8*T8/2))^(2/3)*$D8^0.5/$E8) -> 0.0018822782 | V8: =T8+IF(U8<$B8,1,-1)*설정!$B$10/2^9 -> 1.4119036 | W8: =IF($D8<=0,0,($C8^2/8*(V8-SIN(V8)))*(($C8^2/8*(V8-SIN(V8)))/($C8*V8/2))^(2/3)*$D8^0.5/$E8) -> 0.0018283472 | X8: =V8+IF(W8<$B8,1,-1)*설정!$B$10/2^10 -> 1.4067507 | Y8: =IF($D8<=0,0,($C8^2/8*(X8-SIN(X8)))*(($C8^2/8*(X8-SIN(X8)))/($C8*X8/2))^(2/3)*$D8^0.5/$E8) -> 0.0018017962 | Z8: =X8+IF(Y8<$B8,1,-1)*설정!$B$10/2^11 -> 1.4041742 | AA8: =IF($D8<=0,0,($C8^2/8*(Z8-SIN(Z8)))*(($C8^2/8*(Z8-SIN(Z8)))/($C8*Z8/2))^(2/3)*$D8^0.5/$E8) -> 0.0017886237 | AB8: =Z8+IF(AA8<$B8,1,-1)*설정!$B$10/2^12 -> 1.4054624 | AC8: =IF($D8<=0,0,($C8^2/8*(AB8-SIN(AB8)))*(($C8^2/8*(AB8-SIN(AB8)))/($C8*AB8/2))^(2/3)*$D8^0.5/$E8) -> 0.0017952014 | AD8: =AB8+IF(AC8<$B8,1,-1)*설정!$B$10/2^13 -> 1.4048183 | AE8: =IF($D8<=0,0,($C8^2/8*(AD8-SIN(AD8)))*(($C8^2/8*(AD8-SIN(AD8)))/($C8*AD8/2))^(2/3)*$D8^0.5/$E8) -> 0.0017919104 | AF8: =AD8+IF(AE8<$B8,1,-1)*설정!$B$10/2^14 -> 1.4044963 | AG8: =IF($D8<=0,0,($C8^2/8*(AF8-SIN(AF8)))*(($C8^2/8*(AF8-SIN(AF8)))/($C8*AF8/2))^(2/3)*$D8^0.5/$E8) -> 0.0017902665 | AH8: =AF8+IF(AG8<$B8,1,-1)*설정!$B$10/2^15 -> 1.4043352 | AI8: =IF($D8<=0,0,($C8^2/8*(AH8-SIN(AH8)))*(($C8^2/8*(AH8-SIN(AH8)))/($C8*AH8/2))^(2/3)*$D8^0.5/$E8) -> 0.0017894449 | AJ8: =AH8+IF(AI8<$B8,1,-1)*설정!$B$10/2^16 -> 1.4042547 | AK8: =IF($D8<=0,0,($C8^2/8*(AJ8-SIN(AJ8)))*(($C8^2/8*(AJ8-SIN(AJ8)))/($C8*AJ8/2))^(2/3)*$D8^0.5/$E8) -> 0.0017890343 | AL8: =AJ8+IF(AK8<$B8,1,-1)*설정!$B$10/2^17 -> 1.4042145 | AM8: =IF($D8<=0,0,($C8^2/8*(AL8-SIN(AL8)))*(($C8^2/8*(AL8-SIN(AL8)))/($C8*AL8/2))^(2/3)*$D8^0.5/$E8) -> 0.001788829 | AN8: =AL8+IF(AM8<$B8,1,-1)*설정!$B$10/2^18 -> 1.4042346 | AO8: =IF($D8<=0,0,($C8^2/8*(AN8-SIN(AN8)))*(($C8^2/8*(AN8-SIN(AN8)))/($C8*AN8/2))^(2/3)*$D8^0.5/$E8) -> 0.0017889316 | AP8: =AN8+IF(AO8<$B8,1,-1)*설정!$B$10/2^19 -> 1.4042446 | AQ8: =IF($D8<=0,0,($C8^2/8*(AP8-SIN(AP8)))*(($C8^2/8*(AP8-SIN(AP8)))/($C8*AP8/2))^(2/3)*$D8^0.5/$E8) -> 0.0017889829 | AR8: =AP8+IF(AQ8<$B8,1,-1)*설정!$B$10/2^20 -> 1.4042497 | AS8: =IF($D8<=0,0,($C8^2/8*(AR8-SIN(AR8)))*(($C8^2/8*(AR8-SIN(AR8)))/($C8*AR8/2))^(2/3)*$D8^0.5/$E8) -> 0.0017890086 | AT8: =AR8+IF(AS8<$B8,1,-1)*설정!$B$10/2^21 -> 1.4042472 | AU8: =IF($D8<=0,0,($C8^2/8*(AT8-SIN(AT8)))*(($C8^2/8*(AT8-SIN(AT8)))/($C8*AT8/2))^(2/3)*$D8^0.5/$E8) -> 0.0017889958 | AV8: =AT8+IF(AU8<$B8,1,-1)*설정!$B$10/2^22 -> 1.4042484 | AW8: =IF($D8<=0,0,($C8^2/8*(AV8-SIN(AV8)))*(($C8^2/8*(AV8-SIN(AV8)))/($C8*AV8/2))^(2/3)*$D8^0.5/$E8) -> 0.0017890022 | AX8: =AV8+IF(AW8<$B8,1,-1)*설정!$B$10/2^23 -> 1.404249 | AY8: =IF($D8<=0,0,($C8^2/8*(AX8-SIN(AX8)))*(($C8^2/8*(AX8-SIN(AX8)))/($C8*AX8/2))^(2/3)*$D8^0.5/$E8) -> 0.0017890054 | AZ8: =AX8+IF(AY8<$B8,1,-1)*설정!$B$10/2^24 -> 1.4042487 | BA8: =IF($D8<=0,0,($C8^2/8*(AZ8-SIN(AZ8)))*(($C8^2/8*(AZ8-SIN(AZ8)))/($C8*AZ8/2))^(2/3)*$D8^0.5/$E8) -> 0.0017890038 | BB8: =AZ8+IF(BA8<$B8,1,-1)*설정!$B$10/2^25 -> 1.4042489 | BC8: =IF($D8<=0,0,($C8^2/8*(BB8-SIN(BB8)))*(($C8^2/8*(BB8-SIN(BB8)))/($C8*BB8/2))^(2/3)*$D8^0.5/$E8) -> 0.0017890046 | BD8: =BB8+IF(BC8<$B8,1,-1)*설정!$B$10/2^26 -> 1.404249 | BE8: =IF($D8<=0,0,($C8^2/8*(BD8-SIN(BD8)))*(($C8^2/8*(BD8-SIN(BD8)))/($C8*BD8/2))^(2/3)*$D8^0.5/$E8) -> 0.001789005 | BF8: =BD8+IF(BE8<$B8,1,-1)*설정!$B$10/2^27 -> 1.4042489 | BG8: =IF($D8<=0,0,($C8^2/8*(BF8-SIN(BF8)))*(($C8^2/8*(BF8-SIN(BF8)))/($C8*BF8/2))^(2/3)*$D8^0.5/$E8) -> 0.0017890048 | BH8: =BF8+IF(BG8<$B8,1,-1)*설정!$B$10/2^28 -> 1.4042489 | BI8: =IF($D8<=0,0,($C8^2/8*(BH8-SIN(BH8)))*(($C8^2/8*(BH8-SIN(BH8)))/($C8*BH8/2))^(2/3)*$D8^0.5/$E8) -> 0.0017890047 | BJ8: =BH8+IF(BI8<$B8,1,-1)*설정!$B$10/2^29 -> 1.4042489 | BK8: =IF($D8<=0,0,($C8^2/8*(BJ8-SIN(BJ8)))*(($C8^2/8*(BJ8-SIN(BJ8)))/($C8*BJ8/2))^(2/3)*$D8^0.5/$E8) -> 0.0017890046 | BL8: =BJ8+IF(BK8<$B8,1,-1)*설정!$B$10/2^30 -> 1.4042489 | BM8: =IF($D8<=0,0,($C8^2/8*(BL8-SIN(BL8)))*(($C8^2/8*(BL8-SIN(BL8)))/($C8*BL8/2))^(2/3)*$D8^0.5/$E8) -> 0.0017890046 | BN8: =BL8+IF(BM8<$B8,1,-1)*설정!$B$10/2^31 -> 1.4042489 | BO8: =IF($D8<=0,0,($C8^2/8*(BN8-SIN(BN8)))*(($C8^2/8*(BN8-SIN(BN8)))/($C8*BN8/2))^(2/3)*$D8^0.5/$E8) -> 0.0017890046 | BP8: =BN8+IF(BO8<$B8,1,-1)*설정!$B$10/2^32 -> 1.4042489 | BQ8: =IF($D8<=0,0,($C8^2/8*(BP8-SIN(BP8)))*(($C8^2/8*(BP8-SIN(BP8)))/($C8*BP8/2))^(2/3)*$D8^0.5/$E8) -> 0.0017890046 | BR8: =BP8+IF(BQ8<$B8,1,-1)*설정!$B$10/2^33 -> 1.4042489 | BS8: =IF($D8<=0,0,($C8^2/8*(BR8-SIN(BR8)))*(($C8^2/8*(BR8-SIN(BR8)))/($C8*BR8/2))^(2/3)*$D8^0.5/$E8) -> 0.0017890046 | BT8: =BR8+IF(BS8<$B8,1,-1)*설정!$B$10/2^34 -> 1.4042489 | BU8: =IF($D8<=0,0,($C8^2/8*(BT8-SIN(BT8)))*(($C8^2/8*(BT8-SIN(BT8)))/($C8*BT8/2))^(2/3)*$D8^0.5/$E8) -> 0.0017890046 | BV8: =BT8+IF(BU8<$B8,1,-1)*설정!$B$10/2^35 -> 1.4042489 | BW8: =IF($D8<=0,0,($C8^2/8*(BV8-SIN(BV8)))*(($C8^2/8*(BV8-SIN(BV8)))/($C8*BV8/2))^(2/3)*$D8^0.5/$E8) -> 0.0017890046 | BX8: =BV8+IF(BW8<$B8,1,-1)*설정!$B$10/2^36 -> 1.4042489 | BY8: =IF($D8<=0,0,($C8^2/8*(BX8-SIN(BX8)))*(($C8^2/8*(BX8-SIN(BX8)))/($C8*BX8/2))^(2/3)*$D8^0.5/$E8) -> 0.0017890046 | BZ8: =BX8+IF(BY8<$B8,1,-1)*설정!$B$10/2^37 -> 1.4042489 | CA8: =IF($D8<=0,0,($C8^2/8*(BZ8-SIN(BZ8)))*(($C8^2/8*(BZ8-SIN(BZ8)))/($C8*BZ8/2))^(2/3)*$D8^0.5/$E8) -> 0.0017890046 | CB8: =BZ8+IF(CA8<$B8,1,-1)*설정!$B$10/2^38 -> 1.4042489 | CC8: =IF($D8<=0,0,($C8^2/8*(CB8-SIN(CB8)))*(($C8^2/8*(CB8-SIN(CB8)))/($C8*CB8/2))^(2/3)*$D8^0.5/$E8) -> 0.0017890046 | CD8: =CB8+IF(CC8<$B8,1,-1)*설정!$B$10/2^39 -> 1.4042489 | CE8: =IF($D8<=0,0,($C8^2/8*(CD8-SIN(CD8)))*(($C8^2/8*(CD8-SIN(CD8)))/($C8*CD8/2))^(2/3)*$D8^0.5/$E8) -> 0.0017890046 | CF8: =CD8+IF(CE8<$B8,1,-1)*설정!$B$10/2^40 -> 1.4042489 | CG8: =IF($D8<=0,0,($C8^2/8*(CF8-SIN(CF8)))*(($C8^2/8*(CF8-SIN(CF8)))/($C8*CF8/2))^(2/3)*$D8^0.5/$E8) -> 0.0017890046 | CH8: =CF8+IF(CG8<$B8,1,-1)*설정!$B$10/2^41 -> 1.4042489
A9: =계산!A9 -> BC-05 | B9: =계산!E9 -> 0.0017890046 | C9: =입력!E9/1000 -> 0.2 | D9: =(입력!F9-입력!G9)/입력!D9 -> 0.0254 | E9: =입력!J9 -> 0.011 | F9: =설정!$B$10/2 -> 2.6383016 | G9: =IF($D9<=0,0,($C9^2/8*(F9-SIN(F9)))*(($C9^2/8*(F9-SIN(F9)))/($C9*F9/2))^(2/3)*$D9^0.5/$E9) -> 0.018528316 | H9: =F9+IF(G9<$B9,1,-1)*설정!$B$10/2^2 -> 1.3191508 | I9: =IF($D9<=0,0,($C9^2/8*(H9-SIN(H9)))*(($C9^2/8*(H9-SIN(H9)))/($C9*H9/2))^(2/3)*$D9^0.5/$E9) -> 0.0014252608 | J9: =H9+IF(I9<$B9,1,-1)*설정!$B$10/2^3 -> 1.9787262 | K9: =IF($D9<=0,0,($C9^2/8*(J9-SIN(J9)))*(($C9^2/8*(J9-SIN(J9)))/($C9*J9/2))^(2/3)*$D9^0.5/$E9) -> 0.00688273 | L9: =J9+IF(K9<$B9,1,-1)*설정!$B$10/2^4 -> 1.6489385 | M9: =IF($D9<=0,0,($C9^2/8*(L9-SIN(L9)))*(($C9^2/8*(L9-SIN(L9)))/($C9*L9/2))^(2/3)*$D9^0.5/$E9) -> 0.0034533412 | N9: =L9+IF(M9<$B9,1,-1)*설정!$B$10/2^5 -> 1.4840447 | O9: =IF($D9<=0,0,($C9^2/8*(N9-SIN(N9)))*(($C9^2/8*(N9-SIN(N9)))/($C9*N9/2))^(2/3)*$D9^0.5/$E9) -> 0.0022843025 | P9: =N9+IF(O9<$B9,1,-1)*설정!$B$10/2^6 -> 1.4015977 | Q9: =IF($D9<=0,0,($C9^2/8*(P9-SIN(P9)))*(($C9^2/8*(P9-SIN(P9)))/($C9*P9/2))^(2/3)*$D9^0.5/$E9) -> 0.0018190081 | R9: =P9+IF(Q9<$B9,1,-1)*설정!$B$10/2^7 -> 1.3603743 | S9: =IF($D9<=0,0,($C9^2/8*(R9-SIN(R9)))*(($C9^2/8*(R9-SIN(R9)))/($C9*R9/2))^(2/3)*$D9^0.5/$E9) -> 0.0016135825 | T9: =R9+IF(S9<$B9,1,-1)*설정!$B$10/2^8 -> 1.380986 | U9: =IF($D9<=0,0,($C9^2/8*(T9-SIN(T9)))*(($C9^2/8*(T9-SIN(T9)))/($C9*T9/2))^(2/3)*$D9^0.5/$E9) -> 0.0017141077 | V9: =T9+IF(U9<$B9,1,-1)*설정!$B$10/2^9 -> 1.3912919 | W9: =IF($D9<=0,0,($C9^2/8*(V9-SIN(V9)))*(($C9^2/8*(V9-SIN(V9)))/($C9*V9/2))^(2/3)*$D9^0.5/$E9) -> 0.0017660049 | X9: =V9+IF(W9<$B9,1,-1)*설정!$B$10/2^10 -> 1.3964448 | Y9: =IF($D9<=0,0,($C9^2/8*(X9-SIN(X9)))*(($C9^2/8*(X9-SIN(X9)))/($C9*X9/2))^(2/3)*$D9^0.5/$E9) -> 0.0017923675 | Z9: =X9+IF(Y9<$B9,1,-1)*설정!$B$10/2^11 -> 1.3938683 | AA9: =IF($D9<=0,0,($C9^2/8*(Z9-SIN(Z9)))*(($C9^2/8*(Z9-SIN(Z9)))/($C9*Z9/2))^(2/3)*$D9^0.5/$E9) -> 0.0017791515 | AB9: =Z9+IF(AA9<$B9,1,-1)*설정!$B$10/2^12 -> 1.3951566 | AC9: =IF($D9<=0,0,($C9^2/8*(AB9-SIN(AB9)))*(($C9^2/8*(AB9-SIN(AB9)))/($C9*AB9/2))^(2/3)*$D9^0.5/$E9) -> 0.0017857508 | AD9: =AB9+IF(AC9<$B9,1,-1)*설정!$B$10/2^13 -> 1.3958007 | AE9: =IF($D9<=0,0,($C9^2/8*(AD9-SIN(AD9)))*(($C9^2/8*(AD9-SIN(AD9)))/($C9*AD9/2))^(2/3)*$D9^0.5/$E9) -> 0.001789057 | AF9: =AD9+IF(AE9<$B9,1,-1)*설정!$B$10/2^14 -> 1.3954786 | AG9: =IF($D9<=0,0,($C9^2/8*(AF9-SIN(AF9)))*(($C9^2/8*(AF9-SIN(AF9)))/($C9*AF9/2))^(2/3)*$D9^0.5/$E9) -> 0.0017874034 | AH9: =AF9+IF(AG9<$B9,1,-1)*설정!$B$10/2^15 -> 1.3956396 | AI9: =IF($D9<=0,0,($C9^2/8*(AH9-SIN(AH9)))*(($C9^2/8*(AH9-SIN(AH9)))/($C9*AH9/2))^(2/3)*$D9^0.5/$E9) -> 0.00178823 | AJ9: =AH9+IF(AI9<$B9,1,-1)*설정!$B$10/2^16 -> 1.3957202 | AK9: =IF($D9<=0,0,($C9^2/8*(AJ9-SIN(AJ9)))*(($C9^2/8*(AJ9-SIN(AJ9)))/($C9*AJ9/2))^(2/3)*$D9^0.5/$E9) -> 0.0017886435 | AL9: =AJ9+IF(AK9<$B9,1,-1)*설정!$B$10/2^17 -> 1.3957604 | AM9: =IF($D9<=0,0,($C9^2/8*(AL9-SIN(AL9)))*(($C9^2/8*(AL9-SIN(AL9)))/($C9*AL9/2))^(2/3)*$D9^0.5/$E9) -> 0.0017888502 | AN9: =AL9+IF(AM9<$B9,1,-1)*설정!$B$10/2^18 -> 1.3957806 | AO9: =IF($D9<=0,0,($C9^2/8*(AN9-SIN(AN9)))*(($C9^2/8*(AN9-SIN(AN9)))/($C9*AN9/2))^(2/3)*$D9^0.5/$E9) -> 0.0017889536 | AP9: =AN9+IF(AO9<$B9,1,-1)*설정!$B$10/2^19 -> 1.3957906 | AQ9: =IF($D9<=0,0,($C9^2/8*(AP9-SIN(AP9)))*(($C9^2/8*(AP9-SIN(AP9)))/($C9*AP9/2))^(2/3)*$D9^0.5/$E9) -> 0.0017890053 | AR9: =AP9+IF(AQ9<$B9,1,-1)*설정!$B$10/2^20 -> 1.3957856 | AS9: =IF($D9<=0,0,($C9^2/8*(AR9-SIN(AR9)))*(($C9^2/8*(AR9-SIN(AR9)))/($C9*AR9/2))^(2/3)*$D9^0.5/$E9) -> 0.0017889794 | AT9: =AR9+IF(AS9<$B9,1,-1)*설정!$B$10/2^21 -> 1.3957881 | AU9: =IF($D9<=0,0,($C9^2/8*(AT9-SIN(AT9)))*(($C9^2/8*(AT9-SIN(AT9)))/($C9*AT9/2))^(2/3)*$D9^0.5/$E9) -> 0.0017889924 | AV9: =AT9+IF(AU9<$B9,1,-1)*설정!$B$10/2^22 -> 1.3957894 | AW9: =IF($D9<=0,0,($C9^2/8*(AV9-SIN(AV9)))*(($C9^2/8*(AV9-SIN(AV9)))/($C9*AV9/2))^(2/3)*$D9^0.5/$E9) -> 0.0017889988 | AX9: =AV9+IF(AW9<$B9,1,-1)*설정!$B$10/2^23 -> 1.39579 | AY9: =IF($D9<=0,0,($C9^2/8*(AX9-SIN(AX9)))*(($C9^2/8*(AX9-SIN(AX9)))/($C9*AX9/2))^(2/3)*$D9^0.5/$E9) -> 0.001789002 | AZ9: =AX9+IF(AY9<$B9,1,-1)*설정!$B$10/2^24 -> 1.3957903 | BA9: =IF($D9<=0,0,($C9^2/8*(AZ9-SIN(AZ9)))*(($C9^2/8*(AZ9-SIN(AZ9)))/($C9*AZ9/2))^(2/3)*$D9^0.5/$E9) -> 0.0017890037 | BB9: =AZ9+IF(BA9<$B9,1,-1)*설정!$B$10/2^25 -> 1.3957905 | BC9: =IF($D9<=0,0,($C9^2/8*(BB9-SIN(BB9)))*(($C9^2/8*(BB9-SIN(BB9)))/($C9*BB9/2))^(2/3)*$D9^0.5/$E9) -> 0.0017890045 | BD9: =BB9+IF(BC9<$B9,1,-1)*설정!$B$10/2^26 -> 1.3957905 | BE9: =IF($D9<=0,0,($C9^2/8*(BD9-SIN(BD9)))*(($C9^2/8*(BD9-SIN(BD9)))/($C9*BD9/2))^(2/3)*$D9^0.5/$E9) -> 0.0017890049 | BF9: =BD9+IF(BE9<$B9,1,-1)*설정!$B$10/2^27 -> 1.3957905 | BG9: =IF($D9<=0,0,($C9^2/8*(BF9-SIN(BF9)))*(($C9^2/8*(BF9-SIN(BF9)))/($C9*BF9/2))^(2/3)*$D9^0.5/$E9) -> 0.0017890047 | BH9: =BF9+IF(BG9<$B9,1,-1)*설정!$B$10/2^28 -> 1.3957905 | BI9: =IF($D9<=0,0,($C9^2/8*(BH9-SIN(BH9)))*(($C9^2/8*(BH9-SIN(BH9)))/($C9*BH9/2))^(2/3)*$D9^0.5/$E9) -> 0.0017890046 | BJ9: =BH9+IF(BI9<$B9,1,-1)*설정!$B$10/2^29 -> 1.3957905 | BK9: =IF($D9<=0,0,($C9^2/8*(BJ9-SIN(BJ9)))*(($C9^2/8*(BJ9-SIN(BJ9)))/($C9*BJ9/2))^(2/3)*$D9^0.5/$E9) -> 0.0017890046 | BL9: =BJ9+IF(BK9<$B9,1,-1)*설정!$B$10/2^30 -> 1.3957905 | BM9: =IF($D9<=0,0,($C9^2/8*(BL9-SIN(BL9)))*(($C9^2/8*(BL9-SIN(BL9)))/($C9*BL9/2))^(2/3)*$D9^0.5/$E9) -> 0.0017890046 | BN9: =BL9+IF(BM9<$B9,1,-1)*설정!$B$10/2^31 -> 1.3957905 | BO9: =IF($D9<=0,0,($C9^2/8*(BN9-SIN(BN9)))*(($C9^2/8*(BN9-SIN(BN9)))/($C9*BN9/2))^(2/3)*$D9^0.5/$E9) -> 0.0017890046 | BP9: =BN9+IF(BO9<$B9,1,-1)*설정!$B$10/2^32 -> 1.3957905 | BQ9: =IF($D9<=0,0,($C9^2/8*(BP9-SIN(BP9)))*(($C9^2/8*(BP9-SIN(BP9)))/($C9*BP9/2))^(2/3)*$D9^0.5/$E9) -> 0.0017890046 | BR9: =BP9+IF(BQ9<$B9,1,-1)*설정!$B$10/2^33 -> 1.3957905 | BS9: =IF($D9<=0,0,($C9^2/8*(BR9-SIN(BR9)))*(($C9^2/8*(BR9-SIN(BR9)))/($C9*BR9/2))^(2/3)*$D9^0.5/$E9) -> 0.0017890046 | BT9: =BR9+IF(BS9<$B9,1,-1)*설정!$B$10/2^34 -> 1.3957905 | BU9: =IF($D9<=0,0,($C9^2/8*(BT9-SIN(BT9)))*(($C9^2/8*(BT9-SIN(BT9)))/($C9*BT9/2))^(2/3)*$D9^0.5/$E9) -> 0.0017890046 | BV9: =BT9+IF(BU9<$B9,1,-1)*설정!$B$10/2^35 -> 1.3957905 | BW9: =IF($D9<=0,0,($C9^2/8*(BV9-SIN(BV9)))*(($C9^2/8*(BV9-SIN(BV9)))/($C9*BV9/2))^(2/3)*$D9^0.5/$E9) -> 0.0017890046 | BX9: =BV9+IF(BW9<$B9,1,-1)*설정!$B$10/2^36 -> 1.3957905 | BY9: =IF($D9<=0,0,($C9^2/8*(BX9-SIN(BX9)))*(($C9^2/8*(BX9-SIN(BX9)))/($C9*BX9/2))^(2/3)*$D9^0.5/$E9) -> 0.0017890046 | BZ9: =BX9+IF(BY9<$B9,1,-1)*설정!$B$10/2^37 -> 1.3957905 | CA9: =IF($D9<=0,0,($C9^2/8*(BZ9-SIN(BZ9)))*(($C9^2/8*(BZ9-SIN(BZ9)))/($C9*BZ9/2))^(2/3)*$D9^0.5/$E9) -> 0.0017890046 | CB9: =BZ9+IF(CA9<$B9,1,-1)*설정!$B$10/2^38 -> 1.3957905 | CC9: =IF($D9<=0,0,($C9^2/8*(CB9-SIN(CB9)))*(($C9^2/8*(CB9-SIN(CB9)))/($C9*CB9/2))^(2/3)*$D9^0.5/$E9) -> 0.0017890046 | CD9: =CB9+IF(CC9<$B9,1,-1)*설정!$B$10/2^39 -> 1.3957905 | CE9: =IF($D9<=0,0,($C9^2/8*(CD9-SIN(CD9)))*(($C9^2/8*(CD9-SIN(CD9)))/($C9*CD9/2))^(2/3)*$D9^0.5/$E9) -> 0.0017890046 | CF9: =CD9+IF(CE9<$B9,1,-1)*설정!$B$10/2^40 -> 1.3957905 | CG9: =IF($D9<=0,0,($C9^2/8*(CF9-SIN(CF9)))*(($C9^2/8*(CF9-SIN(CF9)))/($C9*CF9/2))^(2/3)*$D9^0.5/$E9) -> 0.0017890046 | CH9: =CF9+IF(CG9<$B9,1,-1)*설정!$B$10/2^41 -> 1.3957905
A10: =계산!A10 -> BC-06 | B10: =계산!E10 -> 0.0017890046 | C10: =입력!E10/1000 -> 0.2 | D10: =(입력!F10-입력!G10)/입력!D10 -> 0.0106 | E10: =입력!J10 -> 0.011 | F10: =설정!$B$10/2 -> 2.6383016 | G10: =IF($D10<=0,0,($C10^2/8*(F10-SIN(F10)))*(($C10^2/8*(F10-SIN(F10)))/($C10*F10/2))^(2/3)*$D10^0.5/$E10) -> 0.01196939 | H10: =F10+IF(G10<$B10,1,-1)*설정!$B$10/2^2 -> 1.3191508 | I10: =IF($D10<=0,0,($C10^2/8*(H10-SIN(H10)))*(($C10^2/8*(H10-SIN(H10)))/($C10*H10/2))^(2/3)*$D10^0.5/$E10) -> 0.00092072604 | J10: =H10+IF(I10<$B10,1,-1)*설정!$B$10/2^3 -> 1.9787262 | K10: =IF($D10<=0,0,($C10^2/8*(J10-SIN(J10)))*(($C10^2/8*(J10-SIN(J10)))/($C10*J10/2))^(2/3)*$D10^0.5/$E10) -> 0.00444628 | L10: =J10+IF(K10<$B10,1,-1)*설정!$B$10/2^4 -> 1.6489385 | M10: =IF($D10<=0,0,($C10^2/8*(L10-SIN(L10)))*(($C10^2/8*(L10-SIN(L10)))/($C10*L10/2))^(2/3)*$D10^0.5/$E10) -> 0.0022308767 | N10: =L10+IF(M10<$B10,1,-1)*설정!$B$10/2^5 -> 1.4840447 | O10: =IF($D10<=0,0,($C10^2/8*(N10-SIN(N10)))*(($C10^2/8*(N10-SIN(N10)))/($C10*N10/2))^(2/3)*$D10^0.5/$E10) -> 0.0014756715 | P10: =N10+IF(O10<$B10,1,-1)*설정!$B$10/2^6 -> 1.5664916 | Q10: =IF($D10<=0,0,($C10^2/8*(P10-SIN(P10)))*(($C10^2/8*(P10-SIN(P10)))/($C10*P10/2))^(2/3)*$D10^0.5/$E10) -> 0.0018263856 | R10: =P10+IF(Q10<$B10,1,-1)*설정!$B$10/2^7 -> 1.5252681 | S10: =IF($D10<=0,0,($C10^2/8*(R10-SIN(R10)))*(($C10^2/8*(R10-SIN(R10)))/($C10*R10/2))^(2/3)*$D10^0.5/$E10) -> 0.0016445272 | T10: =R10+IF(S10<$B10,1,-1)*설정!$B$10/2^8 -> 1.5458798 | U10: =IF($D10<=0,0,($C10^2/8*(T10-SIN(T10)))*(($C10^2/8*(T10-SIN(T10)))/($C10*T10/2))^(2/3)*$D10^0.5/$E10) -> 0.0017338027 | V10: =T10+IF(U10<$B10,1,-1)*설정!$B$10/2^9 -> 1.5561857 | W10: =IF($D10<=0,0,($C10^2/8*(V10-SIN(V10)))*(($C10^2/8*(V10-SIN(V10)))/($C10*V10/2))^(2/3)*$D10^0.5/$E10) -> 0.0017796772 | X10: =V10+IF(W10<$B10,1,-1)*설정!$B$10/2^10 -> 1.5613386 | Y10: =IF($D10<=0,0,($C10^2/8*(X10-SIN(X10)))*(($C10^2/8*(X10-SIN(X10)))/($C10*X10/2))^(2/3)*$D10^0.5/$E10) -> 0.0018029268 | Z10: =X10+IF(Y10<$B10,1,-1)*설정!$B$10/2^11 -> 1.5587622 | AA10: =IF($D10<=0,0,($C10^2/8*(Z10-SIN(Z10)))*(($C10^2/8*(Z10-SIN(Z10)))/($C10*Z10/2))^(2/3)*$D10^0.5/$E10) -> 0.0017912759 | AB10: =Z10+IF(AA10<$B10,1,-1)*설정!$B$10/2^12 -> 1.5574739 | AC10: =IF($D10<=0,0,($C10^2/8*(AB10-SIN(AB10)))*(($C10^2/8*(AB10-SIN(AB10)))/($C10*AB10/2))^(2/3)*$D10^0.5/$E10) -> 0.00178547 | AD10: =AB10+IF(AC10<$B10,1,-1)*설정!$B$10/2^13 -> 1.5581181 | AE10: =IF($D10<=0,0,($C10^2/8*(AD10-SIN(AD10)))*(($C10^2/8*(AD10-SIN(AD10)))/($C10*AD10/2))^(2/3)*$D10^0.5/$E10) -> 0.0017883713 | AF10: =AD10+IF(AE10<$B10,1,-1)*설정!$B$10/2^14 -> 1.5584401 | AG10: =IF($D10<=0,0,($C10^2/8*(AF10-SIN(AF10)))*(($C10^2/8*(AF10-SIN(AF10)))/($C10*AF10/2))^(2/3)*$D10^0.5/$E10) -> 0.0017898232 | AH10: =AF10+IF(AG10<$B10,1,-1)*설정!$B$10/2^15 -> 1.5582791 | AI10: =IF($D10<=0,0,($C10^2/8*(AH10-SIN(AH10)))*(($C10^2/8*(AH10-SIN(AH10)))/($C10*AH10/2))^(2/3)*$D10^0.5/$E10) -> 0.0017890972 | AJ10: =AH10+IF(AI10<$B10,1,-1)*설정!$B$10/2^16 -> 1.5581986 | AK10: =IF($D10<=0,0,($C10^2/8*(AJ10-SIN(AJ10)))*(($C10^2/8*(AJ10-SIN(AJ10)))/($C10*AJ10/2))^(2/3)*$D10^0.5/$E10) -> 0.0017887342 | AL10: =AJ10+IF(AK10<$B10,1,-1)*설정!$B$10/2^17 -> 1.5582388 | AM10: =IF($D10<=0,0,($C10^2/8*(AL10-SIN(AL10)))*(($C10^2/8*(AL10-SIN(AL10)))/($C10*AL10/2))^(2/3)*$D10^0.5/$E10) -> 0.0017889157 | AN10: =AL10+IF(AM10<$B10,1,-1)*설정!$B$10/2^18 -> 1.558259 | AO10: =IF($D10<=0,0,($C10^2/8*(AN10-SIN(AN10)))*(($C10^2/8*(AN10-SIN(AN10)))/($C10*AN10/2))^(2/3)*$D10^0.5/$E10) -> 0.0017890064 | AP10: =AN10+IF(AO10<$B10,1,-1)*설정!$B$10/2^19 -> 1.5582489 | AQ10: =IF($D10<=0,0,($C10^2/8*(AP10-SIN(AP10)))*(($C10^2/8*(AP10-SIN(AP10)))/($C10*AP10/2))^(2/3)*$D10^0.5/$E10) -> 0.0017889611 | AR10: =AP10+IF(AQ10<$B10,1,-1)*설정!$B$10/2^20 -> 1.5582539 | AS10: =IF($D10<=0,0,($C10^2/8*(AR10-SIN(AR10)))*(($C10^2/8*(AR10-SIN(AR10)))/($C10*AR10/2))^(2/3)*$D10^0.5/$E10) -> 0.0017889837 | AT10: =AR10+IF(AS10<$B10,1,-1)*설정!$B$10/2^21 -> 1.5582564 | AU10: =IF($D10<=0,0,($C10^2/8*(AT10-SIN(AT10)))*(($C10^2/8*(AT10-SIN(AT10)))/($C10*AT10/2))^(2/3)*$D10^0.5/$E10) -> 0.0017889951 | AV10: =AT10+IF(AU10<$B10,1,-1)*설정!$B$10/2^22 -> 1.5582577 | AW10: =IF($D10<=0,0,($C10^2/8*(AV10-SIN(AV10)))*(($C10^2/8*(AV10-SIN(AV10)))/($C10*AV10/2))^(2/3)*$D10^0.5/$E10) -> 0.0017890008 | AX10: =AV10+IF(AW10<$B10,1,-1)*설정!$B$10/2^23 -> 1.5582583 | AY10: =IF($D10<=0,0,($C10^2/8*(AX10-SIN(AX10)))*(($C10^2/8*(AX10-SIN(AX10)))/($C10*AX10/2))^(2/3)*$D10^0.5/$E10) -> 0.0017890036 | AZ10: =AX10+IF(AY10<$B10,1,-1)*설정!$B$10/2^24 -> 1.5582586 | BA10: =IF($D10<=0,0,($C10^2/8*(AZ10-SIN(AZ10)))*(($C10^2/8*(AZ10-SIN(AZ10)))/($C10*AZ10/2))^(2/3)*$D10^0.5/$E10) -> 0.001789005 | BB10: =AZ10+IF(BA10<$B10,1,-1)*설정!$B$10/2^25 -> 1.5582585 | BC10: =IF($D10<=0,0,($C10^2/8*(BB10-SIN(BB10)))*(($C10^2/8*(BB10-SIN(BB10)))/($C10*BB10/2))^(2/3)*$D10^0.5/$E10) -> 0.0017890043 | BD10: =BB10+IF(BC10<$B10,1,-1)*설정!$B$10/2^26 -> 1.5582586 | BE10: =IF($D10<=0,0,($C10^2/8*(BD10-SIN(BD10)))*(($C10^2/8*(BD10-SIN(BD10)))/($C10*BD10/2))^(2/3)*$D10^0.5/$E10) -> 0.0017890047 | BF10: =BD10+IF(BE10<$B10,1,-1)*설정!$B$10/2^27 -> 1.5582585 | BG10: =IF($D10<=0,0,($C10^2/8*(BF10-SIN(BF10)))*(($C10^2/8*(BF10-SIN(BF10)))/($C10*BF10/2))^(2/3)*$D10^0.5/$E10) -> 0.0017890045 | BH10: =BF10+IF(BG10<$B10,1,-1)*설정!$B$10/2^28 -> 1.5582586 | BI10: =IF($D10<=0,0,($C10^2/8*(BH10-SIN(BH10)))*(($C10^2/8*(BH10-SIN(BH10)))/($C10*BH10/2))^(2/3)*$D10^0.5/$E10) -> 0.0017890046 | BJ10: =BH10+IF(BI10<$B10,1,-1)*설정!$B$10/2^29 -> 1.5582586 | BK10: =IF($D10<=0,0,($C10^2/8*(BJ10-SIN(BJ10)))*(($C10^2/8*(BJ10-SIN(BJ10)))/($C10*BJ10/2))^(2/3)*$D10^0.5/$E10) -> 0.0017890046 | BL10: =BJ10+IF(BK10<$B10,1,-1)*설정!$B$10/2^30 -> 1.5582586 | BM10: =IF($D10<=0,0,($C10^2/8*(BL10-SIN(BL10)))*(($C10^2/8*(BL10-SIN(BL10)))/($C10*BL10/2))^(2/3)*$D10^0.5/$E10) -> 0.0017890046 | BN10: =BL10+IF(BM10<$B10,1,-1)*설정!$B$10/2^31 -> 1.5582586 | BO10: =IF($D10<=0,0,($C10^2/8*(BN10-SIN(BN10)))*(($C10^2/8*(BN10-SIN(BN10)))/($C10*BN10/2))^(2/3)*$D10^0.5/$E10) -> 0.0017890046 | BP10: =BN10+IF(BO10<$B10,1,-1)*설정!$B$10/2^32 -> 1.5582586 | BQ10: =IF($D10<=0,0,($C10^2/8*(BP10-SIN(BP10)))*(($C10^2/8*(BP10-SIN(BP10)))/($C10*BP10/2))^(2/3)*$D10^0.5/$E10) -> 0.0017890046 | BR10: =BP10+IF(BQ10<$B10,1,-1)*설정!$B$10/2^33 -> 1.5582586 | BS10: =IF($D10<=0,0,($C10^2/8*(BR10-SIN(BR10)))*(($C10^2/8*(BR10-SIN(BR10)))/($C10*BR10/2))^(2/3)*$D10^0.5/$E10) -> 0.0017890046 | BT10: =BR10+IF(BS10<$B10,1,-1)*설정!$B$10/2^34 -> 1.5582586 | BU10: =IF($D10<=0,0,($C10^2/8*(BT10-SIN(BT10)))*(($C10^2/8*(BT10-SIN(BT10)))/($C10*BT10/2))^(2/3)*$D10^0.5/$E10) -> 0.0017890046 | BV10: =BT10+IF(BU10<$B10,1,-1)*설정!$B$10/2^35 -> 1.5582586 | BW10: =IF($D10<=0,0,($C10^2/8*(BV10-SIN(BV10)))*(($C10^2/8*(BV10-SIN(BV10)))/($C10*BV10/2))^(2/3)*$D10^0.5/$E10) -> 0.0017890046 | BX10: =BV10+IF(BW10<$B10,1,-1)*설정!$B$10/2^36 -> 1.5582586 | BY10: =IF($D10<=0,0,($C10^2/8*(BX10-SIN(BX10)))*(($C10^2/8*(BX10-SIN(BX10)))/($C10*BX10/2))^(2/3)*$D10^0.5/$E10) -> 0.0017890046 | BZ10: =BX10+IF(BY10<$B10,1,-1)*설정!$B$10/2^37 -> 1.5582586 | CA10: =IF($D10<=0,0,($C10^2/8*(BZ10-SIN(BZ10)))*(($C10^2/8*(BZ10-SIN(BZ10)))/($C10*BZ10/2))^(2/3)*$D10^0.5/$E10) -> 0.0017890046 | CB10: =BZ10+IF(CA10<$B10,1,-1)*설정!$B$10/2^38 -> 1.5582586 | CC10: =IF($D10<=0,0,($C10^2/8*(CB10-SIN(CB10)))*(($C10^2/8*(CB10-SIN(CB10)))/($C10*CB10/2))^(2/3)*$D10^0.5/$E10) -> 0.0017890046 | CD10: =CB10+IF(CC10<$B10,1,-1)*설정!$B$10/2^39 -> 1.5582586 | CE10: =IF($D10<=0,0,($C10^2/8*(CD10-SIN(CD10)))*(($C10^2/8*(CD10-SIN(CD10)))/($C10*CD10/2))^(2/3)*$D10^0.5/$E10) -> 0.0017890046 | CF10: =CD10+IF(CE10<$B10,1,-1)*설정!$B$10/2^40 -> 1.5582586 | CG10: =IF($D10<=0,0,($C10^2/8*(CF10-SIN(CF10)))*(($C10^2/8*(CF10-SIN(CF10)))/($C10*CF10/2))^(2/3)*$D10^0.5/$E10) -> 0.0017890046 | CH10: =CF10+IF(CG10<$B10,1,-1)*설정!$B$10/2^41 -> 1.5582586
A11: =계산!A11 -> BC-07 | B11: =계산!E11 -> 0.0017890046 | C11: =입력!E11/1000 -> 0.2 | D11: =(입력!F11-입력!G11)/입력!D11 -> 0.0118 | E11: =입력!J11 -> 0.011 | F11: =설정!$B$10/2 -> 2.6383016 | G11: =IF($D11<=0,0,($C11^2/8*(F11-SIN(F11)))*(($C11^2/8*(F11-SIN(F11)))/($C11*F11/2))^(2/3)*$D11^0.5/$E11) -> 0.012628742 | H11: =F11+IF(G11<$B11,1,-1)*설정!$B$10/2^2 -> 1.3191508 | I11: =IF($D11<=0,0,($C11^2/8*(H11-SIN(H11)))*(($C11^2/8*(H11-SIN(H11)))/($C11*H11/2))^(2/3)*$D11^0.5/$E11) -> 0.00097144563 | J11: =H11+IF(I11<$B11,1,-1)*설정!$B$10/2^3 -> 1.9787262 | K11: =IF($D11<=0,0,($C11^2/8*(J11-SIN(J11)))*(($C11^2/8*(J11-SIN(J11)))/($C11*J11/2))^(2/3)*$D11^0.5/$E11) -> 0.0046912101 | L11: =J11+IF(K11<$B11,1,-1)*설정!$B$10/2^4 -> 1.6489385 | M11: =IF($D11<=0,0,($C11^2/8*(L11-SIN(L11)))*(($C11^2/8*(L11-SIN(L11)))/($C11*L11/2))^(2/3)*$D11^0.5/$E11) -> 0.0023537679 | N11: =L11+IF(M11<$B11,1,-1)*설정!$B$10/2^5 -> 1.4840447 | O11: =IF($D11<=0,0,($C11^2/8*(N11-SIN(N11)))*(($C11^2/8*(N11-SIN(N11)))/($C11*N11/2))^(2/3)*$D11^0.5/$E11) -> 0.0015569611 | P11: =N11+IF(O11<$B11,1,-1)*설정!$B$10/2^6 -> 1.5664916 | Q11: =IF($D11<=0,0,($C11^2/8*(P11-SIN(P11)))*(($C11^2/8*(P11-SIN(P11)))/($C11*P11/2))^(2/3)*$D11^0.5/$E11) -> 0.0019269948 | R11: =P11+IF(Q11<$B11,1,-1)*설정!$B$10/2^7 -> 1.5252681 | S11: =IF($D11<=0,0,($C11^2/8*(R11-SIN(R11)))*(($C11^2/8*(R11-SIN(R11)))/($C11*R11/2))^(2/3)*$D11^0.5/$E11) -> 0.0017351184 | T11: =R11+IF(S11<$B11,1,-1)*설정!$B$10/2^8 -> 1.5458798 | U11: =IF($D11<=0,0,($C11^2/8*(T11-SIN(T11)))*(($C11^2/8*(T11-SIN(T11)))/($C11*T11/2))^(2/3)*$D11^0.5/$E11) -> 0.0018293118 | V11: =T11+IF(U11<$B11,1,-1)*설정!$B$10/2^9 -> 1.535574 | W11: =IF($D11<=0,0,($C11^2/8*(V11-SIN(V11)))*(($C11^2/8*(V11-SIN(V11)))/($C11*V11/2))^(2/3)*$D11^0.5/$E11) -> 0.0017817826 | X11: =V11+IF(W11<$B11,1,-1)*설정!$B$10/2^10 -> 1.5407269 | Y11: =IF($D11<=0,0,($C11^2/8*(X11-SIN(X11)))*(($C11^2/8*(X11-SIN(X11)))/($C11*X11/2))^(2/3)*$D11^0.5/$E11) -> 0.0018054386 | Z11: =X11+IF(Y11<$B11,1,-1)*설정!$B$10/2^11 -> 1.5381504 | AA11: =IF($D11<=0,0,($C11^2/8*(Z11-SIN(Z11)))*(($C11^2/8*(Z11-SIN(Z11)))/($C11*Z11/2))^(2/3)*$D11^0.5/$E11) -> 0.0017935835 | AB11: =Z11+IF(AA11<$B11,1,-1)*설정!$B$10/2^12 -> 1.5368622 | AC11: =IF($D11<=0,0,($C11^2/8*(AB11-SIN(AB11)))*(($C11^2/8*(AB11-SIN(AB11)))/($C11*AB11/2))^(2/3)*$D11^0.5/$E11) -> 0.0017876763 | AD11: =AB11+IF(AC11<$B11,1,-1)*설정!$B$10/2^13 -> 1.5375063 | AE11: =IF($D11<=0,0,($C11^2/8*(AD11-SIN(AD11)))*(($C11^2/8*(AD11-SIN(AD11)))/($C11*AD11/2))^(2/3)*$D11^0.5/$E11) -> 0.0017906282 | AF11: =AD11+IF(AE11<$B11,1,-1)*설정!$B$10/2^14 -> 1.5371843 | AG11: =IF($D11<=0,0,($C11^2/8*(AF11-SIN(AF11)))*(($C11^2/8*(AF11-SIN(AF11)))/($C11*AF11/2))^(2/3)*$D11^0.5/$E11) -> 0.0017891518 | AH11: =AF11+IF(AG11<$B11,1,-1)*설정!$B$10/2^15 -> 1.5370232 | AI11: =IF($D11<=0,0,($C11^2/8*(AH11-SIN(AH11)))*(($C11^2/8*(AH11-SIN(AH11)))/($C11*AH11/2))^(2/3)*$D11^0.5/$E11) -> 0.001788414 | AJ11: =AH11+IF(AI11<$B11,1,-1)*설정!$B$10/2^16 -> 1.5371038 | AK11: =IF($D11<=0,0,($C11^2/8*(AJ11-SIN(AJ11)))*(($C11^2/8*(AJ11-SIN(AJ11)))/($C11*AJ11/2))^(2/3)*$D11^0.5/$E11) -> 0.0017887829 | AL11: =AJ11+IF(AK11<$B11,1,-1)*설정!$B$10/2^17 -> 1.537144 | AM11: =IF($D11<=0,0,($C11^2/8*(AL11-SIN(AL11)))*(($C11^2/8*(AL11-SIN(AL11)))/($C11*AL11/2))^(2/3)*$D11^0.5/$E11) -> 0.0017889673 | AN11: =AL11+IF(AM11<$B11,1,-1)*설정!$B$10/2^18 -> 1.5371641 | AO11: =IF($D11<=0,0,($C11^2/8*(AN11-SIN(AN11)))*(($C11^2/8*(AN11-SIN(AN11)))/($C11*AN11/2))^(2/3)*$D11^0.5/$E11) -> 0.0017890596 | AP11: =AN11+IF(AO11<$B11,1,-1)*설정!$B$10/2^19 -> 1.5371541 | AQ11: =IF($D11<=0,0,($C11^2/8*(AP11-SIN(AP11)))*(($C11^2/8*(AP11-SIN(AP11)))/($C11*AP11/2))^(2/3)*$D11^0.5/$E11) -> 0.0017890135 | AR11: =AP11+IF(AQ11<$B11,1,-1)*설정!$B$10/2^20 -> 1.537149 | AS11: =IF($D11<=0,0,($C11^2/8*(AR11-SIN(AR11)))*(($C11^2/8*(AR11-SIN(AR11)))/($C11*AR11/2))^(2/3)*$D11^0.5/$E11) -> 0.0017889904 | AT11: =AR11+IF(AS11<$B11,1,-1)*설정!$B$10/2^21 -> 1.5371516 | AU11: =IF($D11<=0,0,($C11^2/8*(AT11-SIN(AT11)))*(($C11^2/8*(AT11-SIN(AT11)))/($C11*AT11/2))^(2/3)*$D11^0.5/$E11) -> 0.0017890019 | AV11: =AT11+IF(AU11<$B11,1,-1)*설정!$B$10/2^22 -> 1.5371528 | AW11: =IF($D11<=0,0,($C11^2/8*(AV11-SIN(AV11)))*(($C11^2/8*(AV11-SIN(AV11)))/($C11*AV11/2))^(2/3)*$D11^0.5/$E11) -> 0.0017890077 | AX11: =AV11+IF(AW11<$B11,1,-1)*설정!$B$10/2^23 -> 1.5371522 | AY11: =IF($D11<=0,0,($C11^2/8*(AX11-SIN(AX11)))*(($C11^2/8*(AX11-SIN(AX11)))/($C11*AX11/2))^(2/3)*$D11^0.5/$E11) -> 0.0017890048 | AZ11: =AX11+IF(AY11<$B11,1,-1)*설정!$B$10/2^24 -> 1.5371519 | BA11: =IF($D11<=0,0,($C11^2/8*(AZ11-SIN(AZ11)))*(($C11^2/8*(AZ11-SIN(AZ11)))/($C11*AZ11/2))^(2/3)*$D11^0.5/$E11) -> 0.0017890034 | BB11: =AZ11+IF(BA11<$B11,1,-1)*설정!$B$10/2^25 -> 1.537152 | BC11: =IF($D11<=0,0,($C11^2/8*(BB11-SIN(BB11)))*(($C11^2/8*(BB11-SIN(BB11)))/($C11*BB11/2))^(2/3)*$D11^0.5/$E11) -> 0.0017890041 | BD11: =BB11+IF(BC11<$B11,1,-1)*설정!$B$10/2^26 -> 1.5371521 | BE11: =IF($D11<=0,0,($C11^2/8*(BD11-SIN(BD11)))*(($C11^2/8*(BD11-SIN(BD11)))/($C11*BD11/2))^(2/3)*$D11^0.5/$E11) -> 0.0017890045 | BF11: =BD11+IF(BE11<$B11,1,-1)*설정!$B$10/2^27 -> 1.5371522 | BG11: =IF($D11<=0,0,($C11^2/8*(BF11-SIN(BF11)))*(($C11^2/8*(BF11-SIN(BF11)))/($C11*BF11/2))^(2/3)*$D11^0.5/$E11) -> 0.0017890046 | BH11: =BF11+IF(BG11<$B11,1,-1)*설정!$B$10/2^28 -> 1.5371521 | BI11: =IF($D11<=0,0,($C11^2/8*(BH11-SIN(BH11)))*(($C11^2/8*(BH11-SIN(BH11)))/($C11*BH11/2))^(2/3)*$D11^0.5/$E11) -> 0.0017890045 | BJ11: =BH11+IF(BI11<$B11,1,-1)*설정!$B$10/2^29 -> 1.5371521 | BK11: =IF($D11<=0,0,($C11^2/8*(BJ11-SIN(BJ11)))*(($C11^2/8*(BJ11-SIN(BJ11)))/($C11*BJ11/2))^(2/3)*$D11^0.5/$E11) -> 0.0017890046 | BL11: =BJ11+IF(BK11<$B11,1,-1)*설정!$B$10/2^30 -> 1.5371521 | BM11: =IF($D11<=0,0,($C11^2/8*(BL11-SIN(BL11)))*(($C11^2/8*(BL11-SIN(BL11)))/($C11*BL11/2))^(2/3)*$D11^0.5/$E11) -> 0.0017890046 | BN11: =BL11+IF(BM11<$B11,1,-1)*설정!$B$10/2^31 -> 1.5371522 | BO11: =IF($D11<=0,0,($C11^2/8*(BN11-SIN(BN11)))*(($C11^2/8*(BN11-SIN(BN11)))/($C11*BN11/2))^(2/3)*$D11^0.5/$E11) -> 0.0017890046 | BP11: =BN11+IF(BO11<$B11,1,-1)*설정!$B$10/2^32 -> 1.5371522 | BQ11: =IF($D11<=0,0,($C11^2/8*(BP11-SIN(BP11)))*(($C11^2/8*(BP11-SIN(BP11)))/($C11*BP11/2))^(2/3)*$D11^0.5/$E11) -> 0.0017890046 | BR11: =BP11+IF(BQ11<$B11,1,-1)*설정!$B$10/2^33 -> 1.5371522 | BS11: =IF($D11<=0,0,($C11^2/8*(BR11-SIN(BR11)))*(($C11^2/8*(BR11-SIN(BR11)))/($C11*BR11/2))^(2/3)*$D11^0.5/$E11) -> 0.0017890046 | BT11: =BR11+IF(BS11<$B11,1,-1)*설정!$B$10/2^34 -> 1.5371522 | BU11: =IF($D11<=0,0,($C11^2/8*(BT11-SIN(BT11)))*(($C11^2/8*(BT11-SIN(BT11)))/($C11*BT11/2))^(2/3)*$D11^0.5/$E11) -> 0.0017890046 | BV11: =BT11+IF(BU11<$B11,1,-1)*설정!$B$10/2^35 -> 1.5371522 | BW11: =IF($D11<=0,0,($C11^2/8*(BV11-SIN(BV11)))*(($C11^2/8*(BV11-SIN(BV11)))/($C11*BV11/2))^(2/3)*$D11^0.5/$E11) -> 0.0017890046 | BX11: =BV11+IF(BW11<$B11,1,-1)*설정!$B$10/2^36 -> 1.5371522 | BY11: =IF($D11<=0,0,($C11^2/8*(BX11-SIN(BX11)))*(($C11^2/8*(BX11-SIN(BX11)))/($C11*BX11/2))^(2/3)*$D11^0.5/$E11) -> 0.0017890046 | BZ11: =BX11+IF(BY11<$B11,1,-1)*설정!$B$10/2^37 -> 1.5371522 | CA11: =IF($D11<=0,0,($C11^2/8*(BZ11-SIN(BZ11)))*(($C11^2/8*(BZ11-SIN(BZ11)))/($C11*BZ11/2))^(2/3)*$D11^0.5/$E11) -> 0.0017890046 | CB11: =BZ11+IF(CA11<$B11,1,-1)*설정!$B$10/2^38 -> 1.5371522 | CC11: =IF($D11<=0,0,($C11^2/8*(CB11-SIN(CB11)))*(($C11^2/8*(CB11-SIN(CB11)))/($C11*CB11/2))^(2/3)*$D11^0.5/$E11) -> 0.0017890046 | CD11: =CB11+IF(CC11<$B11,1,-1)*설정!$B$10/2^39 -> 1.5371522 | CE11: =IF($D11<=0,0,($C11^2/8*(CD11-SIN(CD11)))*(($C11^2/8*(CD11-SIN(CD11)))/($C11*CD11/2))^(2/3)*$D11^0.5/$E11) -> 0.0017890046 | CF11: =CD11+IF(CE11<$B11,1,-1)*설정!$B$10/2^40 -> 1.5371522 | CG11: =IF($D11<=0,0,($C11^2/8*(CF11-SIN(CF11)))*(($C11^2/8*(CF11-SIN(CF11)))/($C11*CF11/2))^(2/3)*$D11^0.5/$E11) -> 0.0017890046 | CH11: =CF11+IF(CG11<$B11,1,-1)*설정!$B$10/2^41 -> 1.5371522
